Workbook
Name BICSFI: 'Overview of Revisions'!#REF!
Name BICSGOVT: 'Overview of Revisions'!#REF!
Name EQUITY: 'Overview of Revisions'!#REF!
Name GOVSECTOR: 'Overview of Revisions'!$B$159
Name LANG: 'How To Download'!$C$4
Name LANG4MAP: 'Mapping for Fixed Income'!$B$2
Name LANG4MAP: 'Mapping for Equity'!$B$2
Name OVERTOP: 'Overview of Revisions'!$A$1:$A$1
Name TICKER: 'BICS Fixed Income'!$A$5
Name TICKER: 'How To Download'!$B$5
Name TOP: 'Table of Contents'!$A$3

Sheet Table of Contents
B3: Table of Contents
B4: 1 | C4: Overview of Revisions | D4: - | E4: Overview of Revisions to BICS Equity 2024 Hierarchy
B5: 2 | C5: BICS Equity 2024 Hierarchy | D5: - | E5: BICS Equity 2024 Hierarchy (Level 1 ~ 7) with Codes, Names, and Definitions
B6: 3 | C6: BICS Fixed Income Hierarchy | D6: - | E6: BICS Fixed Income 2014 Hierarchy (Level 1 ~ 2) with Codes and Names
B7: 4 | C7: How To Download | D7: - | E7: Tutorial on How To Download BICS Data Through API
B8: 5 | C8: Mapping for Equity | D8: - | E8: Mapping Between BICS Equity 2020 Hierarchy and BICS Equity 2024 Hierarchy
B9: 6 | C9: Mapping for Fixed Income | D9: - | E9: Mapping Between BICS Equity 2024 Hierarchy and BICS Fixed Income 2014 Hierarchy
B10: 8 | C10: Comparison Template | D10: - | E10: API Template that provide BICS Equity 2024 Classification Data For a List of Entities
B12: Notes:
B13: * | C13: The BICS hierarchy revision is implemented only for Equity. Legacy BICS (DS199, DS201, DS202) remains the same.
B14: ** | C14: BICS fixed income hierarchy remains the same until further notice.

Sheet Overview of Revisions
O1: Back to Table of Contents
B3: Overview of BICS 2024 Revisions (Effective Date: June 7, 2024)
B6: Sector Moves for previous BICS Classifications - These classifications moved from one sector to another sector in the BICS hierarchy
B7: BICS Code | C7: Level | D7: BICS Name | E7: BICS Sector | F7: Prior BICS Code | G7: Prior BICS Sector
B8: 1411111311 | C8: 5 | D8: Financial Transaction Processors | E8: Financials | F8: 1911111210 | G8: Technology
B9: 1411111312 | C9: 5 | D9: Financial Info Services | E9: Financials | F9: 1911111110 | G9: Technology
B10: 141111131210 | C10: 6 | D10: Credit Agencies | E10: Financials | F10: 191111111010 | G10: Technology
B11: 141111131211 | C11: 6 | D11: Data & Analytics | E11: Financials | F11: 191111111011 | G11: Technology
B13: Dropped BICS Classifications - These are BICS Equity 2020 classifications that were removed from the BICS hierarchy
B14: BICS Code | C14: Level | D14: BICS Name | E14: BICS Sector
B15: 171113101310 | C15: 6 | D15: Environ Consulting Services | E15: Industrials
B16: 171113101311 | C16: 6 | D16: Environ Engineering Services | E16: Industrials
B17: 19111111 | C17: 4 | D17: Information Services | E17: Technology
B18: 1911111111 | C18: 5 | D18: Non-Financial Info Services | E18: Technology
B19: 191111111110 | C19: 6 | D19: Health Care Information | E19: Technology
B20: 191111111111 | C20: 6 | D20: Legal Information | E20: Technology
B21: 191111111112 | C21: 6 | D21: Real Estate Information | E21: Technology
B22: 191111111113 | C22: 6 | D22: Scientific Information | E22: Technology
B23: 191111111114 | C23: 6 | D23: Technology Information | E23: Technology
B24: 19111112 | C24: 4 | D24: Data & Transaction Processors | E24: Technology
B25: 1911111211 | C25: 5 | D25: Non-Financial Data Processors | E25: Technology
B27: New BICS Classifications for Entity assignment - These classifications already existed for Segment assignment only
B28: BICS Code | C28: Level | D28: BICS Name | E28: BICS Sector
B29: 111011101010 | C29: 6 | D29: Cars - Electric | E29: Consumer Discretionary
B30: 111011101011 | C30: 6 | D30: Cars - Fossil Fuels | E30: Consumer Discretionary
B31: 111011101110 | C31: 6 | D31: Light Trucks - Electric | E31: Consumer Discretionary
B32: 111011101111 | C32: 6 | D32: Light Trucks - Fossil Fuels | E32: Consumer Discretionary
B33: 111011101210 | C33: 6 | D33: Motorcycles - Electric | E33: Consumer Discretionary
B34: 111011101211 | C34: 6 | D34: Motorcycles - Fossil Fuels | E34: Consumer Discretionary
B35: 11121110131010 | C35: 7 | D35: Passenger Veh Leasing - Electric | E35: Consumer Discretionary
B36: 11121110131011 | C36: 7 | D36: Passenger Veh Leasing - Fossil Fuels | E36: Consumer Discretionary
B37: 11121110131110 | C37: 7 | D37: Passenger Veh Rental - Electric | E37: Consumer Discretionary
B38: 11121110131111 | C38: 7 | D38: Passenger Veh Rental - Fossil Fuels | E38: Consumer Discretionary
B39: 14111110111110 | C39: 7 | D39: Comml Veh Fin & Leasing - Electric | E39: Financials
B40: 14111110111111 | C40: 7 | D40: Comml Veh Fin & Leasing - Fossil Fuels | E40: Financials
... B89: 201011101013 | C89: 6 | D89: CO2 Transmission & Storage | E89: Utilities
B91: New BICS Classifications - These classifications were added in the BICS Equity 2024 hierarchy
B92: BICS Code | C92: Level | D92: BICS Name | E92: BICS Sector
B93: 101012101013 | C93: 6 | D93: Online Film & TV Streaming | E93: Communications
B94: 1010141024 | C94: 5 | D94: Online Transport & Delivery Svcs | E94: Communications
...

Sheet BICS Equity Hierarchy 2024
H2: Back to Table of Contents
G3: =HYPERLINK("bbg://screens/ICS BICS","Click HERE to see the BICS hierarchy on terminal") -> Click HERE to see the BICS hierarchy on terminal
B4: Changes | C4: BICS Code | D4: Level | E4: BICS Name | F4: BICS Name (Long Name) | G4: Definitions | H4: 日本語 DX616=2 | I4: Français DX616=3 | J4: Deutsch DX616=4 | K4: Español DX616=5 | L4: Português DX616=6 | M4: Italiano DX616=7 | N4: 繁體中文 DX616=8 | O4: 한국어 DX616=9 | P4: 简体中文 DX616=10 | Q4: Русский DX616=16
C5: 10 | D5: 1 | E5: Communications | F5: Communications | G5: This sector includes companies facilitating communication or creating and distributing content. | H5: 通信 | I5: Communications | J5: Kommunikation | K5: Comunicaciones | L5: Comunicações | M5: Comunicazioni | N5: 通訊 | O5: 통신 | P5: 通讯 | Q5: Коммуникации
C6: 1010 | D6: 2 | E6: Media | F6: Media | G6: This industry group includes companies that create, distribute, or publish media content. Media content includes many formats, such as print, advertisements, motion pictures, television, music, radio, and Internet websites. Also included are cable and satellite providers. | H6: ﾒﾃﾞｨｱ | I6: Médias | J6: Medien | K6: Prensa | L6: Mídia | M6: Media | N6: 媒體 | O6: 미디어 | P6: 媒体 | Q6: СМИ
C7: 101010 | D7: 3 | E7: Advertising & Marketing | F7: Advertising & Marketing | G7: This industry includes companies that provide advertising and marketing services. Includes the creation of advertising campaigns for use in media, display, or direct mail advertising and other related services. | H7: 広告･ﾏｰｹﾃｨﾝｸﾞ | I7: Publicité et marketing | J7: Werbung & Marketing | K7: Publicidad y mercadeo | L7: Publicidade e Marketing | M7: Pubblicità e marketing | N7: 廣告及行銷 | O7: 광고 & 마케팅 | P7: 广告与营销 | Q7: Реклама и маркетинг
C8: 10101010 | D8: 4 | E8: Advertising & Marketing | F8: Advertising & Marketing | G8: This industry subgroup includes companies that provide advertising and marketing services. Includes the creation of advertising campaigns for use in media, display, or direct mail advertising and other related services. | H8: 広告･ﾏｰｹﾃｨﾝｸﾞ | I8: Publicité et marketing | J8: Werbung & Marketing | K8: Publicidad y mercadeo | L8: Publicidade e Marketing | M8: Pubblicità e marketing | N8: 廣告及行銷 | O8: 광고 & 마케팅 | P8: 广告营销 | Q8: Реклама и маркетинг
C9: 1010101010 | D9: 5 | E9: Advertising Agencies & Svcs | F9: Advertising Agencies & Related Service | G9: This segment includes companies that create advertising campaigns for media use, provide market research or marketing consulting services, or act as public relations or media representatives. | H9: 広告代理店･関連ｻｰﾋﾞｽ | I9: Agences/serv de publicité | J9: Werbeagenturen & -dienste | K9: Servicios y agencias de publicidad | L9: Agências de publicidade e serv | M9: Agenzie e serv pubblicitari | N9: 廣告代理及服務 | O9: 광고 대행사 & 관련 서비스 | P9: 广告代理商及相关服务 | Q9: Рекламн. агентства и услг
C10: 101010101010 | D10: 6 | E10: Advertising Agencies | F10: Advertising Agencies | G10: This segment includes companies that create advertising campaigns for use in newspapers, magazines, radio, television or other media. | H10: 広告代理店 | I10: Agences de pub | J10: Werbeagenturen | K10: Agencias publicidad | L10: Agências de propaganda | M10: Soctà pubblicitarie | N10: 廣告代理業 | O10: 광고대행사 | P10: 广告代理 | Q10: Рекламные агентства
C11: 101010101011 | D11: 6 | E11: E-Marketing | F11: E-Marketing | G11: This segment includes companies that specialize in creating advertising campaigns via Internet media. Includes email marketing, mobile and website advertising, search engine optimization, and social media marketing. | H11: eﾏｰｹﾃｨﾝｸﾞ | I11: E-Marketing | J11: E-Marketing | K11: E-Marketing | L11: Marketing online | M11: E-Marketing | N11: 電子行銷 | O11: E-마케팅 | P11: 网络营销 | Q11: Эл. маркетинг
C12: 101010101012 | D12: 6 | E12: Market Research & Consulting | F12: Market Research & Consulting | G12: This segment includes companies that provide market research, opinion polling or marketing consulting services. | H12: 市場調査･ｺﾝｻﾙﾃｨﾝｸﾞ | I12: Etude de marché et conseil | J12: Marktforschung & Beratung | K12: Estudios y consultoría de mercado | L12: Consultoria e pesquisa de mercado | M12: Consulenza e ricerca di mercato | N12: 市場研究及顧問 | O12: 시장 리서치 & 컨설팅 | P12: 市场研究和顾问 | Q12: Исследования рынка и консалтинг
C13: 10101010101210 | D13: 7 | E13: Marketing Consulting Services | F13: Marketing Consulting Services | G13: This segment includes companies that provide marketing consulting services. | H13: ﾏｰｹﾃｨﾝｸﾞｺﾝｻﾙﾃｨﾝｸﾞｻｰﾋﾞｽ | I13: Services de conseils en marketing | J13: Marketing-Consulting-Dienste | K13: Servicios de consultoría de mercadotecnia | L13: Serviços de consultoria de marketing | M13: Servizi consulenza marketing | N13: 行銷顧問服務 | O13: 시장 컨설팅 서비스 | P13: 营销咨询服务 | Q13: Консультационные услуги по маркетингу
C14: 10101010101211 | D14: 7 | E14: Market Research | F14: Market Research | G14: This segment includes companies that provide market research and opinion polling. | H14: 市場調査 | I14: Etudes de marché | J14: Marktforschung | K14: Estudios del mercado | L14: Pesquisas de mercado | M14: Ricerche di mercato | N14: 市場研究及意見調查 | O14: 시장 리서치 | P14: 市场研究 | Q14: Исследования рынка
C15: 101010101013 | D15: 6 | E15: Media Representatives | F15: Media Representatives | G15: This segment includes companies that sell media time or space on behalf of media owners. | H15: ﾒﾃﾞｨｱﾚｯﾌﾟ | I15: Représentants de médias | J15: Medienvertreter | K15: Agencias de representación de medios | L15: Representantes mídia | M15: Rappresentanti dei media | N15: 媒體代表 | O15: 광고매체판매업 | P15: 媒体代表 | Q15: Представитель средств рекламы
C16: 101010101014 | D16: 6 | E16: Public Relations Agencies | F16: Public Relations Agencies | G16: This segment includes companies that provide public relations services. Public relations services manage the communication and spread of information between their clients and the public. | H16: 広報代理店 | I16: Services de relations publiques | J16: Public-Relations-Agenturen | K16: Agencias de relaciones públicas | L16: Agências de relações públicas | M16: Agenzie di pubbliche relazioni | N16: 公共關係代理 | O16: 홍보기관 | P16: 公关代理 | Q16: Агентства по связьм с общественностью
... C34: 101012101012 | D34: 6 | E34: Teleprod & Postprod Services | F34: Teleproduction & Postproduction Services | G34: This segment includes companies that provide postproduction services for film and TV. Includes editing film, titling, subtitling, credits, and closed captioning. | H34: 番組制作･編集ｻｰﾋﾞｽ | I34: Services de téléprod et postproduction | J34: Fernsehprod. & Nachbearbeitungsdienste | K34: Servicios de tele producción y post producción | L34: Serviços de teleprodução pós prod | M34: Servizi teleprod e postprod | N34: 影像製作及後製服務 | O34: 영상제작 & 영상물 편집 서비스업 | P34: 影像制作及后期制作服务 | Q34: Телепроизв. и проч. монтажн. услуги
B35: New | C35: 101012101013 | D35: 6 | E35: Online Film & TV Streaming | F35: Online Film & TV Streaming | G35: This segment includes companies that create, acquire distribution rights, and distribute film and television shows directly to consumers online via websites or mobile applications. Excludes companies that do not produce content. | H35: ｵﾝﾗｲﾝ映画&TVｽﾄﾘｰﾐﾝｸﾞ | I35: Streaming de films/TV en ligne | J35: Streaming von Filmen & TV online | K35: Películas online y TV por streaming | L35: Streaming de filmes e TV on-line | M35: Film e TV in streaming online | N35: 線上影片及電視串流 | O35: 온라인 영화 & TV 스트리밍 | P35: 在线影视流媒体 | Q35: Онлайн вещание - фильмы и ТВ
C36: 1010121011 | D36: 5 | E36: TV Media Networks | F36: TV Media Networks | G36: This segment includes companies that aggregate, market, and distribute television programs to TV broadcasting stations, cable companies, satellite companies, and wireline telecommunications companies. Programming may be produced in-house or acquired from external sources. | H36: ﾃﾚﾋﾞﾒﾃﾞｨｱﾈｯﾄﾜｰｸ | I36: TV, médias, réseaux | J36: TV Mediennetzwerke | K36: Estaciones de medios p/tv | L36: Redes mídia televisiva | M36: Reti media TV | N36: 電視媒體網路 | O36: TV 미디어 네트워크 | P36: 电视媒体网络 | Q36: Сети ТВ-СМИ
C37: 101012101110 | D37: 6 | E37: Cable Networks | F37: Cable Networks | G37: This segment includes companies that aggregate, market, and distribute television programs to cable companies, satellite companies, and wireline telecommunications companies. These networks negotiate with local and international distributors to broadcast programming on a subscription or fee basis. | H37: ｹｰﾌﾞﾙﾈｯﾄﾜｰｸ | I37: Réseaux de câble | J37: Kabelnetze | K37: Redes de cable | L37: Redes a cabo | M37: Canali TV via cavo | N37: 有線網路 | O37: 케이블 네트워크 | P37: 有线网络 | Q37: Кабельные сети
C38: 10101210111010 | D38: 7 | E38: Adv Rev - Cable Networks | F38: Advertising Revenue - Cable Networks | G38: This segment includes revenue that cable networks generate from advertising. | H38: 広告売上高-ｹｰﾌﾞﾙﾈｯﾄﾜｰｸ | I38: Rev pub-réseaux de câble | J38: Werbeerlös - Kabelnetze | K38: Ingreso de publicidad-redes de cable | L38: Rec prop - Redes a cabo | M38: Ric pubb - Reti via cavo | N38: 廣告收入-有線網路 | O38: 광고 수익 - 케이블 네트워크 | P38: 广告收入-有线网络 | Q38: Рекл. врчк - кабельные сети
C39: 10101210111011 | D39: 7 | E39: Other Rev - Cable Networks | F39: Other Revenue - Cable Networks | G39: This segment includes revenue that cable networks generate from sources other than advertising. | H39: その他売上高-ｹｰﾌﾞﾙﾈｯﾄﾜｰｸ | I39: Autres rev- Réseaux de câble | J39: Sonstiger Erlös - Kabelnetze | K39: Otro ing-redes de cable | L39: Out rec- Redes a cabo | M39: Altri ric - Reti via cavo | N39: 其他收入-有線網路 | O39: 기타 수익 - 케이블 네트워크 | P39: 其他收入-有线网络 | Q39: Пр. выручка - кабельные сети
C40: 101012101111 | D40: 6 | E40: TV Broadcast Networks | F40: TV Broadcast Networks | G40: This segment includes companies that aggregate, market, and distribute television programs to affiliate TV broadcasting stations. These stations then transmit the programming to viewers over public airways. | H40: ﾃﾚﾋﾞ放送ﾈｯﾄﾜｰｸ | I40: Réseaux de diffusion TV | J40: TV Rundfunknetzwerke | K40: Estaciones de tv | L40: Redes transmissão televisiva | M40: Reti trasmissione TV | N40: 電視播放網路 | O40: TV 방송국 네트워크 | P40: 电视广播网络 | Q40: Сети телевещания
C41: 10101210111110 | D41: 7 | E41: Adv Rev - TV Broadcast Netw | F41: Advertising Revenue - TV Broadcast Networks | G41: This segment includes revenue that TV broadcast networks generates from advertising. | H41: 広告売上高-ﾃﾚﾋﾞ放送ﾈｯﾄﾜｰｸ | I41: Rev de pub - Réseau de diffusion télé | J41: Werbeerlös - TV Rundfunknetzwerke | K41: Ing an - estación de tv | L41: Rec prop - Redes transm televisiva | M41: Ric pub-rete TV | N41: 廣告收入-電視播放網路 | O41: 광고수익-TV 방송국 네트워크 | P41: 广告收入-电视广播网络 | Q41: Рекл. выручка - Сети телевещания
C42: 10101210111111 | D42: 7 | E42: Other Rev - TV Broadcast Netw | F42: Other Revenue - TV Broadcast Networks | G42: This segment includes revenue that TV broadcast networks generate from sources other than advertising. | H42: その他売上高-ﾃﾚﾋﾞ放送ﾈｯﾄﾜｰｸ | I42: Autres rev - Rés diffusion TV | J42: Sonst. Erlös - Fernsehübertragungsnetze | K42: Otro ingreso - retransmisión de televisión | L42: Outras rec - Redes transmissão TV | M42: Altri ric - Reti teletrasmissione | N42: 其他收入-電視播放網路 | O42: 기타 수익 - TV 방송국 네트워크 | P42: 其他收入-电视广播网络 | Q42: Пр. выручка -сети телевещ.
C43: 1010121012 | D43: 5 | E43: Royalty Income - Film & TV | F43: Royalty Income - Film & TV | G43: This segment includes companies that generate revenue from their film and television assets (such as trademarks, brand names and/or agreements) for which a royalty payment or licensing fee is paid by others. | H43: ﾛｲﾔﾙﾃｨ収入-映画･ﾃﾚﾋﾞ | I43: Royalties - film et TV | J43: Lizenzerlös - Film & TV | K43: Ing de regalías - películas y TV | L43: Receita de royalty - Filme e TV | M43: Reddito concessioni-Film e TV | N43: 權利金收入-媒體 | O43: 로열티 수익- 영화 & TV | P43: 版权收入-电影与电视 | Q43: Лиценз. сборы - кино- и ТВ
C44: 10101211 | D44: 4 | E44: Music | F44: Music | G44: This industry subgroup includes companies that acquire, produce, and distribute music content. | H44: 音楽 | I44: Musique | J44: Musik | K44: Música | L44: Música | M44: Musica | N44: 音樂製作及發行 | O44: 음악 | P44: 音乐 | Q44: Музыка
C45: 1010121110 | D45: 5 | E45: Integrated Record Prod & Distr | F45: Integrated Record Production & Distribution | G45: This segment includes companies that release, promote, and distribute sound recordings. These companies manufacture, or arrange for the manufacture of recordings, such as audio tapes/cassettes and compact discs, and promote and distribute these products to wholesalers, retailers, or directly to the public. Companies in this segment produce master recordings themselves or obtain reproduction and distribution rights to master recordings produced by record production companies or other integrated record companies. | H45: 総合ﾚｺｰﾄﾞ制作･配給 | I45: Prod int d'enregistrements et distrib | J45: Integrierte Musikprod. & -vertrieb | K45: Produc y distr grabación integr | L45: Prod e dist de gravação integrada | M45: Prod e distrib registrazioni integrate | N45: 整合唱片製作及發行 | O45: 통합 음반 제작 & 배급 | P45: 综合录音制品制作与发行 | Q45: Объед. запись и распрост. пластинок
C46: 1010121111 | D46: 5 | E46: Music Publishers | F46: Music Publishers | G46: This segment includes companies that acquire and register copyrights for musical compositions, and promote and authorize the use of these compositions in recordings, radio, television, motion pictures, live performances, print or other media. Companies in this segment represent the interests of the songwriter or other owners of musical compositions to produce revenues from the use of such works, generally through licensing agreements. These companies may own the copyright or act as administrator of the music copyrights on behalf of copyright owners. Publishers of music books and sheet music are included in this segment. | H46: 音楽出版 | I46: Editeurs de musique | J46: Musikverleger | K46: Editoras de música | L46: Editoras de música | M46: Editori di musica | N46: 音樂出版 | O46: 음반 제작업 | P46: 音乐出版商 | Q46: Издатели муз. произведений
C47: 1010121112 | D47: 5 | E47: Record Production | F47: Record Production | G47: This segment includes companies that produce records, tapes, and compact discs. These companies contract with artists and arrange and finance the production of original master recordings. These companies also hold the copyright to the master recording and derive most of their revenues from the sales, leasing, and licensing of master recordings. Such companies do not have their own duplication or distribution capabilities. | H47: ﾚｺｰﾄﾞ制作 | I47: Prod. enreg. sonore | J47: Musikproduktion | K47: Producción de discos | L47: Produção de disco | M47: Produzione di dischi | N47: 唱片製作 | O47: 음반 제작업 | P47: 录制产品制作 | Q47: Запись пластинок
... C117: 101014102311 | D117: 6 | E117: Other Rev - Social Networking Web | F117: Other Revenue - Social Networking Websites | G117: This segment includes revenue that social networking websites generate from sources other than advertising. | H117: その他売上高-ｿｰｼｬﾙﾈｯﾄﾜｰｷﾝｸﾞWebｻｲﾄ | I117: Autrs rev - Sites Web rés soc | J117: Sonst. Erl. - Social-Networking-Web. | K117: Otro ing - redes sociales | L117: Out rec - Sites da rede social | M117: Altri ric - Web rete sociale | N117: 其他收入-社交網站 | O117: 기타 수익 - 소셜 네트워킹 웹 | P117: 其他收入-社交网络 | Q117: Пр. врчк - Веб-сайты Интернет-сообществ
B118: New | C118: 1010141024 | D118: 5 | E118: Online Transport & Delivery Svcs | F118: Online Transport & Delivery Svcs | G118: This segment includes companies that offer transportation or delivery services online or via applications. These companies do not own the mode of transportation. | H118: ｵﾝﾗｲﾝ輸送･配送ｻｰﾋﾞｽ | I118: Svcs transp/livraison en ligne | J118: Online-Transport- & Lieferdienste | K118: Servicios de transporte y entrega en línea | L118: Serv online de transporte e entrega | M118: Serv di Trasporto e consegna online | N118: 線上運輸及外送服務 | O118: 온라인 운송 및 배달 서비스 | P118: 在线快递物流服务 | Q118: Онлайн услуги транспортировки и доставки
B119: New | C119: 101014102410 | D119: 6 | E119: Online Food Delivery Svcs | F119: Online Food Delivery Svcs | G119: This segment includes companies that offer food delivery services online or via applications. These companies do not own the mode of transportation. | H119: ｵﾝﾗｲﾝ食品配達ｻｰﾋﾞｽ | I119: Svcs de livraison de repas en ligne | J119: Online-Lebensmittellieferungen | K119: Serv en línea de entrega de comida | L119: Serv online para entrega de alimentos | M119: Serv consegna cibo online | N119: 線上食品外送服務 | O119: 온라인 식품 배달 서비스 | P119: 在线外卖服务 | Q119: Онлайн услуги по доставки продуктов питания
B120: New | C120: 101014102411 | D120: 6 | E120: Ridesharing Svcs | F120: Ridesharing Svcs | G120: This segment includes companies that offer ridesharing or other services for the transportation of individuals online or via applications. These companies do not own the mode of transportation. | H120: ﾗｲﾄﾞｼｪｱｻｰﾋﾞｽ | I120: Svcs covoiturage | J120: Mitfahrservice | K120: Serv transporte compartido | L120: Serv de transporte compartilhado | M120: Serv de transporte compartilhado | N120: 共乘服務 | O120: 차량공유 서비스 | P120: 拼车服务 | Q120: Услуги райдшеринга
C121: 1011 | D121: 2 | E121: Telecommunications | F121: Telecommunications | G121: This industry group includes companies that provide telecommunication services. Excludes cable companies that offer telecommunication services. | H121: 電気通信 | I121: Télécommunications | J121: Telekommunikation | K121: Telecomunicaciones | L121: Telecomunicações | M121: Telecomunicazioni | N121: 電信 | O121: 정보통신 | P121: 电信 | Q121: Связь
C122: 101110 | D122: 3 | E122: Telecommunications | F122: Telecommunications | G122: This industry includes companies that provide a broad range of telecommunications services including wireless and wireline services and satellite services including voice, video and/or data. Also includes companies that sell wholesale access to other service providers. Excludes cable multiple system operators (MSOs). (See Cable Cable & Satellite) | H122: 電気通信 | I122: Télécommunications | J122: Telekommunikation | K122: Telecomunicaciones | L122: Telecomunicações | M122: Telecomunicazioni | N122: 電信 | O122: 정보통신 | P122: 电信 | Q122: Связь
C123: 10111010 | D123: 4 | E123: Wireless Telecommunications | F123: Wireless Telecommunications Services | G123: This industry subgroup includes companies that use a wireless infrastructure to provide a variety of services, such as wireless telephony services, wireless data services, text messaging/short messaging services (SMS), roaming, wireless Internet services, and satellite telecommunications. These companies have spectrum licenses and provide services using that spectrum. | H123: 無線通信 | I123: Télécommunications sans fil | J123: Drahtlose Telekommunikation | K123: Telecomunicación inalámbrica | L123: Telecomunicações rede s/fio | M123: Telecomunicazione senza fili | N123: 無線通訊服務 | O123: 무선 정보통신 | P123: 无线电信 | Q123: Беспроводная связь
C124: 1011101010 | D124: 5 | E124: Wireless Service Providers | F124: Wireless Service Providers | G124: This segment includes companies that provide mobile phone services, such as telephone voice services, data services, text messaging services, and roaming services. | H124: ﾜｲﾔﾚｽｻｰﾋﾞｽﾌﾟﾛﾊﾞｲﾀﾞｰ | I124: Fournisseurs services sans fil | J124: Drahtlose Service-Anbieter | K124: Proveedores de servicios inhalámbricos | L124: Provedores de serviços sem fios | M124: Fornitori servizi wireless | N124: 無線服務供應商 | O124: 이동통신서비스 제공업체 | P124: 无线服务供应商 | Q124: Провайдеры беспроводной связи
C125: 101110101010 | D125: 6 | E125: Mobile Phone Services | F125: Mobile Phone Services | G125: This segment includes wireless carriers that offer mobile voice services. | H125: 携帯電話ｻｰﾋﾞｽ | I125: Services téléphoniques mobiles | J125: Mobilfunkdienste | K125: Servicios de teléfono móvil | L125: Serviços de telefone celular | M125: Servizi telefonia mobile | N125: 行動語音服務 | O125: 휴대전화 서비스 | P125: 移动电话服务 | Q125: Услуги мобильных телефонов
C126: 101110101011 | D126: 6 | E126: Mobile Data Services | F126: Mobile Data Services | G126: This segment includes wireless carriers that provide a broad range of mobile data services, such as wireless Internet access, video, games, ring tones, and music. | H126: 携帯通信ﾃﾞｰﾀｻｰﾋﾞｽ | I126: Services données mobiles | J126: Mobile Datendienste | K126: Servicios móviles de datos | L126: Serviços dados móvel | M126: Servizi dati Mobili | N126: 行動數據服務 | O126: 모바일 데이터 서비스 | P126: 移动数据服务 | Q126: Мобильн. усл. данных
C127: 101110101012 | D127: 6 | E127: Mobile Text Messaging (SMS) | F127: Mobile Text Messaging (SMS) | G127: This segment includes wireless carriers that offer mobile short message service (SMS), also known as text messaging. | H127: 携帯ﾃｷｽﾄﾒｯｾｰｼﾞ(SMS) | I127: Message texte (SMS) par mobile | J127: Textnachrichten (SMS) | K127: Mensajes de texto en celulares (SMS) | L127: Mensagem de texto de telefone móvel | M127: Messaggi (SMS) | N127: 行動簡訊(SMS) | O127: 모바일 문자 메시지 (SMS) | P127: 手机短信 (SMS) | Q127: Мобильные текстовые сообщения (SMS)
...

Sheet BICS Fixed Income
H2: =INDEX('How To Download'!$F$70:$F$80,MATCH('BICS Fixed Income'!C4,'How To Download'!$D$70:$D$80,FALSE)) -> 3
C3: LANGUAGE:
C4: English | E4: Back to Table of Contents
B6: No Change To BICS Fixed Income Hierarchy Until Further Notice
B7: ID | C7: Classification Fields
B8: BI011 | C8: BICS_LEVEL_1_SECTOR_CODE
B9: BI012 | C9: BICS_LEVEL_2_INDUSTRY_GROUP_CODE
B10: BI001 | C10: BICS_LEVEL_1_SECTOR_NAME
B11: BI002 | C11: BICS_LEVEL_2_INDUSTRY_GROUP_NAME
B13: LEVEL 1 - SECTOR | D13: LEVEL 2 - INDUSTRY GROUP
B14: 30 | C14: =VLOOKUP(B14,'Current BICS Fixed Income'!$B$5:$P$94,'BICS Fixed Income'!$H$2,FALSE) -> Materials | D14: 3010 | E14: =TRIM(VLOOKUP(D14,'Current BICS Fixed Income'!$B$5:$P$94,'BICS Fixed Income'!$H$2,FALSE)) -> Forest & Paper Products Manufacturing
D15: 3011 | E15: =TRIM(VLOOKUP(D15,'Current BICS Fixed Income'!$B$5:$P$94,'BICS Fixed Income'!$H$2,FALSE)) -> Metals & Mining
D16: 3012 | E16: =TRIM(VLOOKUP(D16,'Current BICS Fixed Income'!$B$5:$P$94,'BICS Fixed Income'!$H$2,FALSE)) -> Construction Materials Manufacturing
D17: 3013 | E17: =TRIM(VLOOKUP(D17,'Current BICS Fixed Income'!$B$5:$P$94,'BICS Fixed Income'!$H$2,FALSE)) -> Chemicals
D18: 3014 | E18: =TRIM(VLOOKUP(D18,'Current BICS Fixed Income'!$B$5:$P$94,'BICS Fixed Income'!$H$2,FALSE)) -> Containers & Packaging
B20: LEVEL 1 - SECTOR | D20: LEVEL 2 - INDUSTRY GROUP
B21: 31 | C21: =TRIM(VLOOKUP(B21,'Current BICS Fixed Income'!$B$5:$P$94,'BICS Fixed Income'!$H$2,FALSE)) -> Communications | D21: 3110 | E21: =TRIM(VLOOKUP(D21,'Current BICS Fixed Income'!$B$5:$P$94,'BICS Fixed Income'!$H$2,FALSE)) -> Cable & Satellite
D22: 3111 | E22: =TRIM(VLOOKUP(D22,'Current BICS Fixed Income'!$B$5:$P$94,'BICS Fixed Income'!$H$2,FALSE)) -> Wireline Telecommunications Services
D23: 3112 | E23: =TRIM(VLOOKUP(D23,'Current BICS Fixed Income'!$B$5:$P$94,'BICS Fixed Income'!$H$2,FALSE)) -> Internet Media
D24: 3113 | E24: =TRIM(VLOOKUP(D24,'Current BICS Fixed Income'!$B$5:$P$94,'BICS Fixed Income'!$H$2,FALSE)) -> Wireless Telecommunications Services
D25: 3114 | E25: =TRIM(VLOOKUP(D25,'Current BICS Fixed Income'!$B$5:$P$94,'BICS Fixed Income'!$H$2,FALSE)) -> Entertainment Content
D26: 3115 | E26: =TRIM(VLOOKUP(D26,'Current BICS Fixed Income'!$B$5:$P$94,'BICS Fixed Income'!$H$2,FALSE)) -> Publishing & Broadcasting
D27: 3116 | E27: =TRIM(VLOOKUP(D27,'Current BICS Fixed Income'!$B$5:$P$94,'BICS Fixed Income'!$H$2,FALSE)) -> Advertising & Marketing
B29: LEVEL 1 - SECTOR | D29: LEVEL 2 - INDUSTRY GROUP
B30: 32 | C30: =TRIM(VLOOKUP(B30,'Current BICS Fixed Income'!$B$5:$P$94,'BICS Fixed Income'!$H$2,FALSE)) -> Consumer Discretionary | D30: 3210 | E30: =TRIM(VLOOKUP(D30,'Current BICS Fixed Income'!$B$5:$P$94,'BICS Fixed Income'!$H$2,FALSE)) -> Leisure Products Manufacturing
D31: 3211 | E31: =TRIM(VLOOKUP(D31,'Current BICS Fixed Income'!$B$5:$P$94,'BICS Fixed Income'!$H$2,FALSE)) -> Automobiles Manufacturing
D32: 3212 | E32: =TRIM(VLOOKUP(D32,'Current BICS Fixed Income'!$B$5:$P$94,'BICS Fixed Income'!$H$2,FALSE)) -> Retail - Consumer Discretionary
D33: 3213 | E33: =TRIM(VLOOKUP(D33,'Current BICS Fixed Income'!$B$5:$P$94,'BICS Fixed Income'!$H$2,FALSE)) -> Airlines
D34: 3214 | E34: =TRIM(VLOOKUP(D34,'Current BICS Fixed Income'!$B$5:$P$94,'BICS Fixed Income'!$H$2,FALSE)) -> Casinos & Gaming
D35: 3215 | E35: =TRIM(VLOOKUP(D35,'Current BICS Fixed Income'!$B$5:$P$94,'BICS Fixed Income'!$H$2,FALSE)) -> Restaurants
D36: 3216 | E36: =TRIM(VLOOKUP(D36,'Current BICS Fixed Income'!$B$5:$P$94,'BICS Fixed Income'!$H$2,FALSE)) -> Travel & Lodging
D37: 3217 | E37: =TRIM(VLOOKUP(D37,'Current BICS Fixed Income'!$B$5:$P$94,'BICS Fixed Income'!$H$2,FALSE)) -> Homebuilders
D38: 3218 | E38: =TRIM(VLOOKUP(D38,'Current BICS Fixed Income'!$B$5:$P$94,'BICS Fixed Income'!$H$2,FALSE)) -> Home Improvement
D39: 3219 | E39: =TRIM(VLOOKUP(D39,'Current BICS Fixed Income'!$B$5:$P$94,'BICS Fixed Income'!$H$2,FALSE)) -> Apparel & Textile Products
D40: 3225 | E40: =TRIM(VLOOKUP(D40,'Current BICS Fixed Income'!$B$5:$P$94,'BICS Fixed Income'!$H$2,FALSE)) -> Home & Office Products Manufacturing
D41: 3226 | E41: =TRIM(VLOOKUP(D41,'Current BICS Fixed Income'!$B$5:$P$94,'BICS Fixed Income'!$H$2,FALSE)) -> Educational Services
D42: 3227 | E42: =TRIM(VLOOKUP(D42,'Current BICS Fixed Income'!$B$5:$P$94,'BICS Fixed Income'!$H$2,FALSE)) -> Entertainment Resources
... D46: 3231 | E46: =TRIM(VLOOKUP(D46,'Current BICS Fixed Income'!$B$5:$P$94,'BICS Fixed Income'!$H$2,FALSE)) -> Department Stores
B48: LEVEL 1 - SECTOR | D48: LEVEL 2 - INDUSTRY GROUP
B49: 33 | C49: =TRIM(VLOOKUP(B49,'Current BICS Fixed Income'!$B$5:$P$94,'BICS Fixed Income'!$H$2,FALSE)) -> Consumer Staples | D49: 3310 | E49: =TRIM(VLOOKUP(D49,'Current BICS Fixed Income'!$B$5:$P$94,'BICS Fixed Income'!$H$2,FALSE)) -> Tobacco
...

Sheet How To Download
B4: Ticker | C4: SECURITY_NAME_LANG | D4: LONG_COMP_NAME
B5: EA US equity | C5: English | D5: {=IF(TICKER="","",_xll.BDP(TICKER,$D$4,LANG,INDEX($E$70:$E$80,MATCH($C$5,$D$70:$D$80,FALSE))))} -> Electronic Arts Inc | H5: Back to Table of Contents
B7: How To view BICS Equity 2024 on Terminal
B9: =HYPERLINK("bbg://screens/ICS BICS","ICS BICS <GO>") -> ICS BICS <GO>
B10: Type ICS BICS<GO> to see revised hierarchy on terminal
B12: =HYPERLINK("bbg://screens/"&TICKER&" CCB BICS",TICKER&" CCB BICS"&"<GO>") -> EA US equity CCB BICS<GO>
B13: Type CCB BICS<GO> to see Company Classification Browser based on BICS hierarchy
B15: How To Download BICS Equity 2024 (Default)
B17: BICS Fields (Returns BICS 2024) | D17: Example: | E17: =BDP(Ticker,"BICS_LEVEL_1_SECTOR_CODE") | I17: *BICS (Level 1~4 with optional level 5~7)
B18: Following classification fields return BICS 2024 codes and names.
B19: ID | C19: Classification Code Field | D19: Level | E19: Classification Code | G19: ID | H19: Classification Name Field | I19: Classification Name
B20: BI011 | C20: BICS_LEVEL_1_SECTOR_CODE | D20: 1 | E20: {=IF(TICKER="","",IF(_xlfn.SINGLE(_xll.BDP(TICKER,C20))="#N/A N/A","",_xll.BDP(TICKER,C20)))} -> 10 | G20: BI001 | H20: BICS_LEVEL_1_SECTOR_NAME | I20: {=IF(TICKER="","",IF(_xlfn.SINGLE(_xll.BDP(TICKER,H20,LANG,INDEX($E$70:$E$80,MATCH($C$5,$D$70:$D$80,FALSE))))="#N/A N/A","",_xll.BDP(TICKER,H20,LANG,INDEX($E$70:$E$80,MATCH($C$5,$D$70:$D$80,FALSE)))))} -> Communications
B21: BI012 | C21: BICS_LEVEL_2_INDUSTRY_GROUP_CODE | D21: 2 | E21: {=IF(TICKER="","",IF(_xlfn.SINGLE(_xll.BDP(TICKER,C21))="#N/A N/A","",_xll.BDP(TICKER,C21)))} -> 1010 | G21: BI002 | H21: BICS_LEVEL_2_INDUSTRY_GROUP_NAME | I21: {=IF(TICKER="","",IF(_xlfn.SINGLE(_xll.BDP(TICKER,H21,LANG,INDEX($E$70:$E$80,MATCH($C$5,$D$70:$D$80,FALSE))))="#N/A N/A","",_xll.BDP(TICKER,H21,LANG,INDEX($E$70:$E$80,MATCH($C$5,$D$70:$D$80,FALSE)))))} -> Media
B22: BI013 | C22: BICS_LEVEL_3_INDUSTRY_CODE | D22: 3 | E22: {=IF(TICKER="","",IF(_xlfn.SINGLE(_xll.BDP(TICKER,C22))="#N/A N/A","",_xll.BDP(TICKER,C22)))} -> 101012 | G22: BI003 | H22: BICS_LEVEL_3_INDUSTRY_NAME | I22: {=IF(TICKER="","",IF(_xlfn.SINGLE(_xll.BDP(TICKER,H22,LANG,INDEX($E$70:$E$80,MATCH($C$5,$D$70:$D$80,FALSE))))="#N/A N/A","",_xll.BDP(TICKER,H22,LANG,INDEX($E$70:$E$80,MATCH($C$5,$D$70:$D$80,FALSE)))))} -> Entertainment Content
B23: BI014 | C23: BICS_LEVEL_4_SUB_INDUSTRY_CODE | D23: 4 | E23: {=IF(TICKER="","",IF(_xlfn.SINGLE(_xll.BDP(TICKER,C23))="#N/A N/A","",_xll.BDP(TICKER,C23)))} -> 10101212 | G23: BI004 | H23: BICS_LEVEL_4_SUB_INDUSTRY_NAME | I23: {=IF(TICKER="","",IF(_xlfn.SINGLE(_xll.BDP(TICKER,H23,LANG,INDEX($E$70:$E$80,MATCH($C$5,$D$70:$D$80,FALSE))))="#N/A N/A","",_xll.BDP(TICKER,H23,LANG,INDEX($E$70:$E$80,MATCH($C$5,$D$70:$D$80,FALSE)))))} -> Video Games
B24: BI015 | C24: BICS_LEVEL_5_SEGMENT_CODE | D24: 5 | E24: {=IF(TICKER="","",IF(_xlfn.SINGLE(_xll.BDP(TICKER,C24))="#N/A N/A","",_xll.BDP(TICKER,C24)))} -> 1010121211 | G24: BI005 | H24: BICS_LEVEL_5_SEGMENT_NAME | I24: {=IF(TICKER="","",IF(_xlfn.SINGLE(_xll.BDP(TICKER,H24,LANG,INDEX($E$70:$E$80,MATCH($C$5,$D$70:$D$80,FALSE))))="#N/A N/A","",_xll.BDP(TICKER,H24,LANG,INDEX($E$70:$E$80,MATCH($C$5,$D$70:$D$80,FALSE)))))} -> Console & PC Games
B25: BI016 | C25: BICS_LEVEL_6_SEGMENT_CODE | D25: 6 | E25: {=IF(TICKER="","",IF(_xlfn.SINGLE(_xll.BDP(TICKER,C25))="#N/A N/A","",_xll.BDP(TICKER,C25)))} | G25: BI006 | H25: BICS_LEVEL_6_SEGMENT_NAME | I25: {=IF(TICKER="","",IF(_xlfn.SINGLE(_xll.BDP(TICKER,H25,LANG,INDEX($E$70:$E$80,MATCH($C$5,$D$70:$D$80,FALSE))))="#N/A N/A","",_xll.BDP(TICKER,H25,LANG,INDEX($E$70:$E$80,MATCH($C$5,$D$70:$D$80,FALSE)))))}
B26: BI017 | C26: BICS_LEVEL_7_SEGMENT_CODE | D26: 7 | E26: {=IF(TICKER="","",IF(_xlfn.SINGLE(_xll.BDP(TICKER,C26))="#N/A N/A","",_xll.BDP(TICKER,C26)))} | G26: BI007 | H26: BICS_LEVEL_7_SEGMENT_NAME | I26: {=IF(TICKER="","",IF(_xlfn.SINGLE(_xll.BDP(TICKER,H26,LANG,INDEX($E$70:$E$80,MATCH($C$5,$D$70:$D$80,FALSE))))="#N/A N/A","",_xll.BDP(TICKER,H26,LANG,INDEX($E$70:$E$80,MATCH($C$5,$D$70:$D$80,FALSE)))))}
B29: How To Download BICS Equity 2024 (Alternative Method 1)
B30: Level Specific Generic Classification Fields
B31: Classification Scheme Override
B32: CLASSIFICATION_SCHEME=BICS | D32: Example: | E32: =BDP(Ticker,"CLASSIFICATION_LEVEL_1_CODE","CLASSIFICATION_SCHEME=BICS")
I33: *BICS (Level 1~4 with optional level 5~7)
B34: Following level specific classification fields can return any available classification codes and names when classification scheme is specified. Use "CLASSIFICATION_SCHEME=BICS" to view BICS 2024 classification
B35: ID | C35: Classification Code Field | D35: Level | E35: Classification Code | G35: ID | H35: Classification Name Field | I35: Classification Name
B36: BI061 | C36: CLASSIFICATION_LEVEL_1_CODE | D36: 1 | E36: =IF(TICKER="","",IF(_xll.BDP(TICKER,C36,"CLASSIFICATION_SCHEME=BICS")="#N/A N/A","",_xll.BDP(TICKER,C36,"CLASSIFICATION_SCHEME=BICS"))) -> 10 | G36: BI071 | H36: CLASSIFICATION_LEVEL_1_NAME | I36: =IF(TICKER="","",IF(_xll.BDP(TICKER,H36,"CLASSIFICATION_SCHEME=BICS",LANG,INDEX($E$70:$E$80,MATCH($C$5,$D$70:$D$80,FALSE)))="#N/A N/A","",_xll.BDP(TICKER,H36,"CLASSIFICATION_SCHEME=BICS",LANG,INDEX($E$70:$E$80,MATCH($C$5,$D$70:$D$80,FALSE))))) -> Communications
B37: BI062 | C37: CLASSIFICATION_LEVEL_2_CODE | D37: 2 | E37: =IF(TICKER="","",IF(_xll.BDP(TICKER,C37,"CLASSIFICATION_SCHEME=BICS")="#N/A N/A","",_xll.BDP(TICKER,C37,"CLASSIFICATION_SCHEME=BICS"))) -> 1010 | G37: BI072 | H37: CLASSIFICATION_LEVEL_2_NAME | I37: =IF(TICKER="","",IF(_xll.BDP(TICKER,H37,"CLASSIFICATION_SCHEME=BICS",LANG,INDEX($E$70:$E$80,MATCH($C$5,$D$70:$D$80,FALSE)))="#N/A N/A","",_xll.BDP(TICKER,H37,"CLASSIFICATION_SCHEME=BICS",LANG,INDEX($E$70:$E$80,MATCH($C$5,$D$70:$D$80,FALSE))))) -> Media
B38: BI063 | C38: CLASSIFICATION_LEVEL_3_CODE | D38: 3 | E38: =IF(TICKER="","",IF(_xll.BDP(TICKER,C38,"CLASSIFICATION_SCHEME=BICS")="#N/A N/A","",_xll.BDP(TICKER,C38,"CLASSIFICATION_SCHEME=BICS"))) -> 101012 | G38: BI073 | H38: CLASSIFICATION_LEVEL_3_NAME | I38: =IF(TICKER="","",IF(_xll.BDP(TICKER,H38,"CLASSIFICATION_SCHEME=BICS",LANG,INDEX($E$70:$E$80,MATCH($C$5,$D$70:$D$80,FALSE)))="#N/A N/A","",_xll.BDP(TICKER,H38,"CLASSIFICATION_SCHEME=BICS",LANG,INDEX($E$70:$E$80,MATCH($C$5,$D$70:$D$80,FALSE))))) -> Entertainment Content
B39: BI064 | C39: CLASSIFICATION_LEVEL_4_CODE | D39: 4 | E39: =IF(TICKER="","",IF(_xll.BDP(TICKER,C39,"CLASSIFICATION_SCHEME=BICS")="#N/A N/A","",_xll.BDP(TICKER,C39,"CLASSIFICATION_SCHEME=BICS"))) -> 10101212 | G39: BI074 | H39: CLASSIFICATION_LEVEL_4_NAME | I39: =IF(TICKER="","",IF(_xll.BDP(TICKER,H39,"CLASSIFICATION_SCHEME=BICS",LANG,INDEX($E$70:$E$80,MATCH($C$5,$D$70:$D$80,FALSE)))="#N/A N/A","",_xll.BDP(TICKER,H39,"CLASSIFICATION_SCHEME=BICS",LANG,INDEX($E$70:$E$80,MATCH($C$5,$D$70:$D$80,FALSE))))) -> Video Games
B40: BI065 | C40: CLASSIFICATION_LEVEL_5_CODE | D40: 5 | E40: =IF(TICKER="","",IF(_xll.BDP(TICKER,C40,"CLASSIFICATION_SCHEME=BICS")="#N/A N/A","",_xll.BDP(TICKER,C40,"CLASSIFICATION_SCHEME=BICS"))) -> 1010121211 | G40: BI075 | H40: CLASSIFICATION_LEVEL_5_NAME | I40: =IF(TICKER="","",IF(_xll.BDP(TICKER,H40,"CLASSIFICATION_SCHEME=BICS",LANG,INDEX($E$70:$E$80,MATCH($C$5,$D$70:$D$80,FALSE)))="#N/A N/A","",_xll.BDP(TICKER,H40,"CLASSIFICATION_SCHEME=BICS",LANG,INDEX($E$70:$E$80,MATCH($C$5,$D$70:$D$80,FALSE))))) -> Console & PC Games
B41: BI066 | C41: CLASSIFICATION_LEVEL_6_CODE | D41: 6 | E41: =IF(TICKER="","",IF(_xll.BDP(TICKER,C41,"CLASSIFICATION_SCHEME=BICS")="#N/A N/A","",_xll.BDP(TICKER,C41,"CLASSIFICATION_SCHEME=BICS"))) | G41: BI076 | H41: CLASSIFICATION_LEVEL_6_NAME | I41: =IF(TICKER="","",IF(_xll.BDP(TICKER,H41,"CLASSIFICATION_SCHEME=BICS",LANG,INDEX($E$70:$E$80,MATCH($C$5,$D$70:$D$80,FALSE)))="#N/A N/A","",_xll.BDP(TICKER,H41,"CLASSIFICATION_SCHEME=BICS",LANG,INDEX($E$70:$E$80,MATCH($C$5,$D$70:$D$80,FALSE)))))
B42: BI067 | C42: CLASSIFICATION_LEVEL_7_CODE | D42: 7 | E42: =IF(TICKER="","",IF(_xll.BDP(TICKER,C42,"CLASSIFICATION_SCHEME=BICS")="#N/A N/A","",_xll.BDP(TICKER,C42,"CLASSIFICATION_SCHEME=BICS"))) | G42: BI077 | H42: CLASSIFICATION_LEVEL_7_NAME | I42: =IF(TICKER="","",IF(_xll.BDP(TICKER,H42,"CLASSIFICATION_SCHEME=BICS",LANG,INDEX($E$70:$E$80,MATCH($C$5,$D$70:$D$80,FALSE)))="#N/A N/A","",_xll.BDP(TICKER,H42,"CLASSIFICATION_SCHEME=BICS",LANG,INDEX($E$70:$E$80,MATCH($C$5,$D$70:$D$80,FALSE)))))
B45: How To Download BICS Equity 2024 (Alternative Method 2)
B46: Generic Classification Fields With Level Override
B47: Classification Scheme and Level Override
B48: CLASSIFICATION_SCHEME=BICS | D48: Example: | E48: =BDP(Ticker,"CLASSIFICATION_CODE","CLASSIFICATION_SCHEME=BICS","CLASSIFICATION_LEVEL=1")
B49: CLASSIFICATION_LEVEL=1
B51: Following classification fields can return any available classification codes and names when classification scheme and classification level are specified. In case of BICS level 4, use "CLASSIFICATION_SCHEME=BICS" and "CLASSIFICATION_LEVEL=4"
B52: ID | C52: Classification Code Field | D52: Level | E52: Classification Code | G52: ID | H52: Classification Name Field | I52: Classification Name
B53: DY843 | C53: CLASSIFICATION_CODE | D53: 1 | E53: =IF(TICKER="","",IF(_xll.BDP(TICKER,"CLASSIFICATION_CODE","CLASSIFICATION_LEVEL",D53,"CLASSIFICATION_SCHEME=BICS")="#N/A N/A","",_xll.BDP(TICKER,"CLASSIFICATION_CODE","CLASSIFICATION_LEVEL",D53,"CLASSIFICATION_SCHEME=BICS"))) -> 10 | G53: DY844 | H53: CLASSIFICATION_DESCRIPTION | I53: =IF(TICKER="","",IF(_xll.BDP(TICKER,"CLASSIFICATION_DESCRIPTION","CLASSIFICATION_LEVEL",D53,"CLASSIFICATION_SCHEME=BICS",LANG,INDEX($E$70:$E$80,MATCH($C$5,$D$70:$D$80,FALSE)))="#N/A N/A","",_xll.BDP(TICKER,"CLASSIFICATION_DESCRIPTION","CLASSIFICATION_LEVEL",D53,"CLASSIFICATION_SCHEME=BICS",LANG,INDEX($E$70:$E$80,MATCH($C$5,$D$70:$D$80,FALSE))))) -> Communications
...

Sheet Mapping for Equity
B1: LANGUAGE: | K1: =INDEX('How To Download'!F70:F80,MATCH(LANG4MAP,'How To Download'!$D$70:$D$80,FALSE)) -> 3
B2: English | J2: Back to Table of Contents
B3: BICS Equity Hierarchy 2020 | H3: Equivalent BICS Equity 2024 Classification
B4: BICS Code | C4: Level | D4: BICS Name | F4: Changes | H4: BICS Code | I4: BICS Name | J4: BICS Code | K4: BICS Name | L4: BICS Code | M4: BICS Name | N4: BICS Code | O4: BICS Name
B5: 10 | C5: 1 | D5: =VLOOKUP(B5,'Current BICS'!$B$4:$P$1837,'Mapping for Equity'!$K$1,FALSE) -> Communications | E5: ⇒ | G5: ⇒ | H5: 10 | I5: =VLOOKUP(H5,'BICS Equity Hierarchy 2024'!$C$5:$Q$1846,'Mapping for Equity'!$K$1,FALSE) -> Communications | K5: =IF(J5="","",VLOOKUP(J5,'BICS Equity Hierarchy 2024'!$C$5:$Q$1783,'Mapping for Equity'!$K$1))
B6: 1010 | C6: 2 | D6: =VLOOKUP(B6,'Current BICS'!$B$4:$P$1837,'Mapping for Equity'!$K$1,FALSE) -> Media | E6: ⇒ | G6: ⇒ | H6: 1010 | I6: =VLOOKUP(H6,'BICS Equity Hierarchy 2024'!$C$5:$Q$1846,'Mapping for Equity'!$K$1,FALSE) -> Media | K6: =IF(J6="","",VLOOKUP(J6,'BICS Equity Hierarchy 2024'!$C$5:$Q$1783,'Mapping for Equity'!$K$1))
B7: 101010 | C7: 3 | D7: =VLOOKUP(B7,'Current BICS'!$B$4:$P$1837,'Mapping for Equity'!$K$1,FALSE) -> Advertising & Marketing | E7: ⇒ | G7: ⇒ | H7: 101010 | I7: =VLOOKUP(H7,'BICS Equity Hierarchy 2024'!$C$5:$Q$1846,'Mapping for Equity'!$K$1,FALSE) -> Advertising & Marketing | K7: =IF(J7="","",VLOOKUP(J7,'BICS Equity Hierarchy 2024'!$C$5:$Q$1783,'Mapping for Equity'!$K$1))
B8: 10101010 | C8: 4 | D8: =VLOOKUP(B8,'Current BICS'!$B$4:$P$1837,'Mapping for Equity'!$K$1,FALSE) -> Advertising & Marketing | E8: ⇒ | G8: ⇒ | H8: 10101010 | I8: =VLOOKUP(H8,'BICS Equity Hierarchy 2024'!$C$5:$Q$1846,'Mapping for Equity'!$K$1,FALSE) -> Advertising & Marketing | K8: =IF(J8="","",VLOOKUP(J8,'BICS Equity Hierarchy 2024'!$C$5:$Q$1783,'Mapping for Equity'!$K$1))
B9: 1010101010 | C9: 5 | D9: =VLOOKUP(B9,'Current BICS'!$B$4:$P$1837,'Mapping for Equity'!$K$1,FALSE) -> Advertising Agencies & Svcs | E9: ⇒ | G9: ⇒ | H9: 1010101010 | I9: =VLOOKUP(H9,'BICS Equity Hierarchy 2024'!$C$5:$Q$1846,'Mapping for Equity'!$K$1,FALSE) -> Advertising Agencies & Svcs | K9: =IF(J9="","",VLOOKUP(J9,'BICS Equity Hierarchy 2024'!$C$5:$Q$1783,'Mapping for Equity'!$K$1))
B10: 101010101010 | C10: 6 | D10: =VLOOKUP(B10,'Current BICS'!$B$4:$P$1837,'Mapping for Equity'!$K$1,FALSE) -> Advertising Agencies | E10: ⇒ | G10: ⇒ | H10: 101010101010 | I10: =VLOOKUP(H10,'BICS Equity Hierarchy 2024'!$C$5:$Q$1846,'Mapping for Equity'!$K$1,FALSE) -> Advertising Agencies | K10: =IF(J10="","",VLOOKUP(J10,'BICS Equity Hierarchy 2024'!$C$5:$Q$1783,'Mapping for Equity'!$K$1))
B11: 101010101011 | C11: 6 | D11: =VLOOKUP(B11,'Current BICS'!$B$4:$P$1837,'Mapping for Equity'!$K$1,FALSE) -> E-Marketing | E11: ⇒ | G11: ⇒ | H11: 101010101011 | I11: =VLOOKUP(H11,'BICS Equity Hierarchy 2024'!$C$5:$Q$1846,'Mapping for Equity'!$K$1,FALSE) -> E-Marketing | K11: =IF(J11="","",VLOOKUP(J11,'BICS Equity Hierarchy 2024'!$C$5:$Q$1783,'Mapping for Equity'!$K$1))
B12: 101010101012 | C12: 6 | D12: =VLOOKUP(B12,'Current BICS'!$B$4:$P$1837,'Mapping for Equity'!$K$1,FALSE) -> Market Research & Consulting | E12: ⇒ | G12: ⇒ | H12: 101010101012 | I12: =VLOOKUP(H12,'BICS Equity Hierarchy 2024'!$C$5:$Q$1846,'Mapping for Equity'!$K$1,FALSE) -> Market Research & Consulting | K12: =IF(J12="","",VLOOKUP(J12,'BICS Equity Hierarchy 2024'!$C$5:$Q$1783,'Mapping for Equity'!$K$1))
B13: 10101010101210 | C13: 7 | D13: =VLOOKUP(B13,'Current BICS'!$B$4:$P$1837,'Mapping for Equity'!$K$1,FALSE) -> Marketing Consulting Services | E13: ⇒ | G13: ⇒ | H13: 10101010101210 | I13: =VLOOKUP(H13,'BICS Equity Hierarchy 2024'!$C$5:$Q$1846,'Mapping for Equity'!$K$1,FALSE) -> Marketing Consulting Services | K13: =IF(J13="","",VLOOKUP(J13,'BICS Equity Hierarchy 2024'!$C$5:$Q$1783,'Mapping for Equity'!$K$1))
B14: 10101010101211 | C14: 7 | D14: =VLOOKUP(B14,'Current BICS'!$B$4:$P$1837,'Mapping for Equity'!$K$1,FALSE) -> Market Research | E14: ⇒ | G14: ⇒ | H14: 10101010101211 | I14: =VLOOKUP(H14,'BICS Equity Hierarchy 2024'!$C$5:$Q$1846,'Mapping for Equity'!$K$1,FALSE) -> Market Research | K14: =IF(J14="","",VLOOKUP(J14,'BICS Equity Hierarchy 2024'!$C$5:$Q$1783,'Mapping for Equity'!$K$1))
B15: 101010101013 | C15: 6 | D15: =VLOOKUP(B15,'Current BICS'!$B$4:$P$1837,'Mapping for Equity'!$K$1,FALSE) -> Media Representatives | E15: ⇒ | G15: ⇒ | H15: 101010101013 | I15: =VLOOKUP(H15,'BICS Equity Hierarchy 2024'!$C$5:$Q$1846,'Mapping for Equity'!$K$1,FALSE) -> Media Representatives | K15: =IF(J15="","",VLOOKUP(J15,'BICS Equity Hierarchy 2024'!$C$5:$Q$1783,'Mapping for Equity'!$K$1))
B16: 101010101014 | C16: 6 | D16: =VLOOKUP(B16,'Current BICS'!$B$4:$P$1837,'Mapping for Equity'!$K$1,FALSE) -> Public Relations Agencies | E16: ⇒ | G16: ⇒ | H16: 101010101014 | I16: =VLOOKUP(H16,'BICS Equity Hierarchy 2024'!$C$5:$Q$1846,'Mapping for Equity'!$K$1,FALSE) -> Public Relations Agencies | K16: =IF(J16="","",VLOOKUP(J16,'BICS Equity Hierarchy 2024'!$C$5:$Q$1783,'Mapping for Equity'!$K$1))
... B187: 11101110 | C187: 4 | D187: =VLOOKUP(B187,'Current BICS'!$B$4:$P$1837,'Mapping for Equity'!$K$1,FALSE) -> Automobiles | E187: ⇒ | G187: ⇒ | H187: 11101110 | I187: =VLOOKUP(H187,'BICS Equity Hierarchy 2024'!$C$5:$Q$1846,'Mapping for Equity'!$K$1,FALSE) -> Automobiles | K187: =IF(J187="","",VLOOKUP(J187,'BICS Equity Hierarchy 2024'!$C$5:$Q$1783,'Mapping for Equity'!$K$1))
B188: 1110111010 | C188: 5 | D188: =VLOOKUP(B188,'Current BICS'!$B$4:$P$1837,'Mapping for Equity'!$K$1,FALSE) -> Passenger Vehicles | E188: ⇒ | F188: Name Changed | G188: ⇒ | H188: 1110111010 | I188: =VLOOKUP(H188,'BICS Equity Hierarchy 2024'!$C$5:$Q$1846,'Mapping for Equity'!$K$1,FALSE) -> Cars | K188: =IF(J188="","",VLOOKUP(J188,'BICS Equity Hierarchy 2024'!$C$5:$Q$1783,'Mapping for Equity'!$K$1))
B189: 111011101010 | C189: 6 | D189: =VLOOKUP(B189,'Current BICS'!$B$4:$P$1837,'Mapping for Equity'!$K$1,FALSE) -> Passenger Vehicles - Electric | E189: ⇒ | F189: Name Changed | G189: ⇒ | H189: 111011101010 | I189: =VLOOKUP(H189,'BICS Equity Hierarchy 2024'!$C$5:$Q$1846,'Mapping for Equity'!$K$1,FALSE) -> Cars - Electric | K189: =IF(J189="","",VLOOKUP(J189,'BICS Equity Hierarchy 2024'!$C$5:$Q$1783,'Mapping for Equity'!$K$1))
B190: 111011101011 | C190: 6 | D190: =VLOOKUP(B190,'Current BICS'!$B$4:$P$1837,'Mapping for Equity'!$K$1,FALSE) -> Passenger Vehicles - Fossil Fuels | E190: ⇒ | F190: Name Changed | G190: ⇒ | H190: 111011101011 | I190: =VLOOKUP(H190,'BICS Equity Hierarchy 2024'!$C$5:$Q$1846,'Mapping for Equity'!$K$1,FALSE) -> Cars - Fossil Fuels | K190: =IF(J190="","",VLOOKUP(J190,'BICS Equity Hierarchy 2024'!$C$5:$Q$1783,'Mapping for Equity'!$K$1))
B191: 1110111011 | C191: 5 | D191: =VLOOKUP(B191,'Current BICS'!$B$4:$P$1837,'Mapping for Equity'!$K$1,FALSE) -> Light Trucks | E191: ⇒ | G191: ⇒ | H191: 1110111011 | I191: =VLOOKUP(H191,'BICS Equity Hierarchy 2024'!$C$5:$Q$1846,'Mapping for Equity'!$K$1,FALSE) -> Light Trucks | K191: =IF(J191="","",VLOOKUP(J191,'BICS Equity Hierarchy 2024'!$C$5:$Q$1783,'Mapping for Equity'!$K$1))
B192: 111011101110 | C192: 6 | D192: =VLOOKUP(B192,'Current BICS'!$B$4:$P$1837,'Mapping for Equity'!$K$1,FALSE) -> Light Trucks - Electric | E192: ⇒ | G192: ⇒ | H192: 111011101110 | I192: =VLOOKUP(H192,'BICS Equity Hierarchy 2024'!$C$5:$Q$1846,'Mapping for Equity'!$K$1,FALSE) -> Light Trucks - Electric | K192: =IF(J192="","",VLOOKUP(J192,'BICS Equity Hierarchy 2024'!$C$5:$Q$1783,'Mapping for Equity'!$K$1))
B193: 111011101111 | C193: 6 | D193: =VLOOKUP(B193,'Current BICS'!$B$4:$P$1837,'Mapping for Equity'!$K$1,FALSE) -> Light Trucks - Fossil Fuels | E193: ⇒ | G193: ⇒ | H193: 111011101111 | I193: =VLOOKUP(H193,'BICS Equity Hierarchy 2024'!$C$5:$Q$1846,'Mapping for Equity'!$K$1,FALSE) -> Light Trucks - Fossil Fuels | K193: =IF(J193="","",VLOOKUP(J193,'BICS Equity Hierarchy 2024'!$C$5:$Q$1783,'Mapping for Equity'!$K$1))
B194: 1110111012 | C194: 5 | D194: =VLOOKUP(B194,'Current BICS'!$B$4:$P$1837,'Mapping for Equity'!$K$1,FALSE) -> Motorcycles | E194: ⇒ | G194: ⇒ | H194: 1110111012 | I194: =VLOOKUP(H194,'BICS Equity Hierarchy 2024'!$C$5:$Q$1846,'Mapping for Equity'!$K$1,FALSE) -> Motorcycles | K194: =IF(J194="","",VLOOKUP(J194,'BICS Equity Hierarchy 2024'!$C$5:$Q$1783,'Mapping for Equity'!$K$1))
B195: 111011101210 | C195: 6 | D195: =VLOOKUP(B195,'Current BICS'!$B$4:$P$1837,'Mapping for Equity'!$K$1,FALSE) -> Motorcycles - Electric | E195: ⇒ | G195: ⇒ | H195: 111011101210 | I195: =VLOOKUP(H195,'BICS Equity Hierarchy 2024'!$C$5:$Q$1846,'Mapping for Equity'!$K$1,FALSE) -> Motorcycles - Electric | K195: =IF(J195="","",VLOOKUP(J195,'BICS Equity Hierarchy 2024'!$C$5:$Q$1783,'Mapping for Equity'!$K$1))
B196: 111011101211 | C196: 6 | D196: =VLOOKUP(B196,'Current BICS'!$B$4:$P$1837,'Mapping for Equity'!$K$1,FALSE) -> Motorcycles - Fossil Fuels | E196: ⇒ | G196: ⇒ | H196: 111011101211 | I196: =VLOOKUP(H196,'BICS Equity Hierarchy 2024'!$C$5:$Q$1846,'Mapping for Equity'!$K$1,FALSE) -> Motorcycles - Fossil Fuels | K196: =IF(J196="","",VLOOKUP(J196,'BICS Equity Hierarchy 2024'!$C$5:$Q$1783,'Mapping for Equity'!$K$1))
B197: 11101111 | C197: 4 | D197: =VLOOKUP(B197,'Current BICS'!$B$4:$P$1837,'Mapping for Equity'!$K$1,FALSE) -> Auto Parts | E197: ⇒ | G197: ⇒ | H197: 11101111 | I197: =VLOOKUP(H197,'BICS Equity Hierarchy 2024'!$C$5:$Q$1846,'Mapping for Equity'!$K$1,FALSE) -> Auto Parts | K197: =IF(J197="","",VLOOKUP(J197,'BICS Equity Hierarchy 2024'!$C$5:$Q$1783,'Mapping for Equity'!$K$1))
B198: 1110111110 | C198: 5 | D198: =VLOOKUP(B198,'Current BICS'!$B$4:$P$1837,'Mapping for Equity'!$K$1,FALSE) -> Alternative Vehicle Parts | E198: ⇒ | G198: ⇒ | H198: 1110111110 | I198: =VLOOKUP(H198,'BICS Equity Hierarchy 2024'!$C$5:$Q$1846,'Mapping for Equity'!$K$1,FALSE) -> Alternative Vehicle Parts | K198: =IF(J198="","",VLOOKUP(J198,'BICS Equity Hierarchy 2024'!$C$5:$Q$1783,'Mapping for Equity'!$K$1))
B199: 1110111111 | C199: 5 | D199: =VLOOKUP(B199,'Current BICS'!$B$4:$P$1837,'Mapping for Equity'!$K$1,FALSE) -> Auto Electrical & Electronics | E199: ⇒ | G199: ⇒ | H199: 1110111111 | I199: =VLOOKUP(H199,'BICS Equity Hierarchy 2024'!$C$5:$Q$1846,'Mapping for Equity'!$K$1,FALSE) -> Auto Electrical & Electronics | K199: =IF(J199="","",VLOOKUP(J199,'BICS Equity Hierarchy 2024'!$C$5:$Q$1783,'Mapping for Equity'!$K$1))
B200: 111011111110 | C200: 6 | D200: =VLOOKUP(B200,'Current BICS'!$B$4:$P$1837,'Mapping for Equity'!$K$1,FALSE) -> Auto Light Equipment | E200: ⇒ | G200: ⇒ | H200: 111011111110 | I200: =VLOOKUP(H200,'BICS Equity Hierarchy 2024'!$C$5:$Q$1846,'Mapping for Equity'!$K$1,FALSE) -> Auto Light Equipment | K200: =IF(J200="","",VLOOKUP(J200,'BICS Equity Hierarchy 2024'!$C$5:$Q$1783,'Mapping for Equity'!$K$1))
B201: 111011111111 | C201: 6 | D201: =VLOOKUP(B201,'Current BICS'!$B$4:$P$1837,'Mapping for Equity'!$K$1,FALSE) -> Auto Electronics | E201: ⇒ | G201: ⇒ | H201: 111011111111 | I201: =VLOOKUP(H201,'BICS Equity Hierarchy 2024'!$C$5:$Q$1846,'Mapping for Equity'!$K$1,FALSE) -> Auto Electronics | K201: =IF(J201="","",VLOOKUP(J201,'BICS Equity Hierarchy 2024'!$C$5:$Q$1783,'Mapping for Equity'!$K$1))
B202: 1110111112 | C202: 5 | D202: =VLOOKUP(B202,'Current BICS'!$B$4:$P$1837,'Mapping for Equity'!$K$1,FALSE) -> Auto Glass | E202: ⇒ | G202: ⇒ | H202: 1110111112 | I202: =VLOOKUP(H202,'BICS Equity Hierarchy 2024'!$C$5:$Q$1846,'Mapping for Equity'!$K$1,FALSE) -> Auto Glass | K202: =IF(J202="","",VLOOKUP(J202,'BICS Equity Hierarchy 2024'!$C$5:$Q$1783,'Mapping for Equity'!$K$1))
... B254: 11101313 | C254: 4 | D254: =VLOOKUP(B254,'Current BICS'!$B$4:$P$1837,'Mapping for Equity'!$K$1,FALSE) -> Office Supplies | E254: ⇒ | G254: ⇒ | H254: 11101313 | I254: =VLOOKUP(H254,'BICS Equity Hierarchy 2024'!$C$5:$Q$1846,'Mapping for Equity'!$K$1,FALSE) -> Office Supplies | K254: =IF(J254="","",VLOOKUP(J254,'BICS Equity Hierarchy 2024'!$C$5:$Q$1783,'Mapping for Equity'!$K$1))
B255: 1110131310 | C255: 5 | D255: =VLOOKUP(B255,'Current BICS'!$B$4:$P$1837,'Mapping for Equity'!$K$1,FALSE) -> Stationary | E255: ⇒ | F255: Name Changed | G255: ⇒ | H255: 1110131310 | I255: =VLOOKUP(H255,'BICS Equity Hierarchy 2024'!$C$5:$Q$1846,'Mapping for Equity'!$K$1,FALSE) -> Stationery | K255: =IF(J255="","",VLOOKUP(J255,'BICS Equity Hierarchy 2024'!$C$5:$Q$1783,'Mapping for Equity'!$K$1))
B256: 1110131311 | C256: 5 | D256: =VLOOKUP(B256,'Current BICS'!$B$4:$P$1837,'Mapping for Equity'!$K$1,FALSE) -> Writing Instruments | E256: ⇒ | G256: ⇒ | H256: 1110131311 | I256: =VLOOKUP(H256,'BICS Equity Hierarchy 2024'!$C$5:$Q$1846,'Mapping for Equity'!$K$1,FALSE) -> Writing Instruments | K256: =IF(J256="","",VLOOKUP(J256,'BICS Equity Hierarchy 2024'!$C$5:$Q$1783,'Mapping for Equity'!$K$1))
B257: 111014 | C257: 3 | D257: =VLOOKUP(B257,'Current BICS'!$B$4:$P$1837,'Mapping for Equity'!$K$1,FALSE) -> Leisure Products | E257: ⇒ | G257: ⇒ | H257: 111014 | I257: =VLOOKUP(H257,'BICS Equity Hierarchy 2024'!$C$5:$Q$1846,'Mapping for Equity'!$K$1,FALSE) -> Leisure Products | K257: =IF(J257="","",VLOOKUP(J257,'BICS Equity Hierarchy 2024'!$C$5:$Q$1783,'Mapping for Equity'!$K$1))
B258: 11101410 | C258: 4 | D258: =VLOOKUP(B258,'Current BICS'!$B$4:$P$1837,'Mapping for Equity'!$K$1,FALSE) -> Toys & Games | E258: ⇒ | G258: ⇒ | H258: 11101410 | I258: =VLOOKUP(H258,'BICS Equity Hierarchy 2024'!$C$5:$Q$1846,'Mapping for Equity'!$K$1,FALSE) -> Toys & Games | K258: =IF(J258="","",VLOOKUP(J258,'BICS Equity Hierarchy 2024'!$C$5:$Q$1783,'Mapping for Equity'!$K$1))
B259: 11101411 | C259: 4 | D259: =VLOOKUP(B259,'Current BICS'!$B$4:$P$1837,'Mapping for Equity'!$K$1,FALSE) -> Music Instruments | E259: ⇒ | G259: ⇒ | H259: 11101411 | I259: =VLOOKUP(H259,'BICS Equity Hierarchy 2024'!$C$5:$Q$1846,'Mapping for Equity'!$K$1,FALSE) -> Music Instruments | K259: =IF(J259="","",VLOOKUP(J259,'BICS Equity Hierarchy 2024'!$C$5:$Q$1783,'Mapping for Equity'!$K$1))
B260: 11101412 | C260: 4 | D260: =VLOOKUP(B260,'Current BICS'!$B$4:$P$1837,'Mapping for Equity'!$K$1,FALSE) -> Recreational Vehicles | E260: ⇒ | G260: ⇒ | H260: 11101412 | I260: =VLOOKUP(H260,'BICS Equity Hierarchy 2024'!$C$5:$Q$1846,'Mapping for Equity'!$K$1,FALSE) -> Recreational Vehicles | K260: =IF(J260="","",VLOOKUP(J260,'BICS Equity Hierarchy 2024'!$C$5:$Q$1783,'Mapping for Equity'!$K$1))
B261: 1110141210 | C261: 5 | D261: =VLOOKUP(B261,'Current BICS'!$B$4:$P$1837,'Mapping for Equity'!$K$1,FALSE) -> Leisure Boats & Yachts Building | E261: ⇒ | G261: ⇒ | H261: 1110141210 | I261: =VLOOKUP(H261,'BICS Equity Hierarchy 2024'!$C$5:$Q$1846,'Mapping for Equity'!$K$1,FALSE) -> Leisure Boats & Yachts Building | K261: =IF(J261="","",VLOOKUP(J261,'BICS Equity Hierarchy 2024'!$C$5:$Q$1783,'Mapping for Equity'!$K$1))
...

Sheet Mapping for Fixed Income
B1: LANGUAGE:
B2: English
B3: BICS Equity 2024 | F3: BICS Fixed Income | H3: Back to Table of Contents
B4: BICS Code | C4: Level | D4: BICS Name | F4: BICS Code | G4: BICS Name
B5: 10 | C5: 1 | D5: Communications | E5: ⇒
B6: 1010 | C6: 2 | D6: Media | E6: ⇒
B7: 101010 | C7: 3 | D7: Advertising & Marketing | E7: ⇒
B8: 10101010 | C8: 4 | D8: Advertising & Marketing | E8: ⇒ | F8: 3116 | G8: Advertising & Marketing
B9: 1010101010 | C9: 5 | D9: Advertising Agencies & Svcs | E9: ⇒ | F9: 3116 | G9: Advertising & Marketing
B10: 101010101010 | C10: 6 | D10: Advertising Agencies | E10: ⇒ | F10: 3116 | G10: Advertising & Marketing
B11: 101010101011 | C11: 6 | D11: E-Marketing | E11: ⇒ | F11: 3116 | G11: Advertising & Marketing
B12: 101010101012 | C12: 6 | D12: Market Research & Consulting | E12: ⇒ | F12: 3116 | G12: Advertising & Marketing
B13: 10101010101210 | C13: 7 | D13: Marketing Consulting Services | E13: ⇒ | F13: 3116 | G13: Advertising & Marketing
B14: 10101010101211 | C14: 7 | D14: Market Research | E14: ⇒ | F14: 3116 | G14: Advertising & Marketing
B15: 101010101013 | C15: 6 | D15: Media Representatives | E15: ⇒ | F15: 3116 | G15: Advertising & Marketing
B16: 101010101014 | C16: 6 | D16: Public Relations Agencies | E16: ⇒ | F16: 3116 | G16: Advertising & Marketing
B17: 1010101011 | C17: 5 | D17: Direct Marketing | E17: ⇒ | F17: 3116 | G17: Advertising & Marketing
B18: 101010101110 | C18: 6 | D18: Advertising Material Distr Svcs | E18: ⇒ | F18: 3116 | G18: Advertising & Marketing
B19: 101010101111 | C19: 6 | D19: Direct Mail Advertising | E19: ⇒ | F19: 3116 | G19: Advertising & Marketing
B20: 101011 | C20: 3 | D20: Cable & Satellite | E20: ⇒
B21: 10101110 | C21: 4 | D21: Cable & Satellite | E21: ⇒ | F21: 3110 | G21: Cable & Satellite
B22: 1010111010 | C22: 5 | D22: Cable & Satellite Video Svcs | E22: ⇒ | F22: 3110 | G22: Cable & Satellite
B23: 1010111011 | C23: 5 | D23: Cable & Satellite Internet Svcs | E23: ⇒ | F23: 3110 | G23: Cable & Satellite
B24: 1010111012 | C24: 5 | D24: Cable & Satellite Phone Svcs | E24: ⇒ | F24: 3110 | G24: Cable & Satellite
B25: 101012 | C25: 3 | D25: Entertainment Content | E25: ⇒
B26: 10101210 | C26: 4 | D26: Film & TV | E26: ⇒ | F26: 3114 | G26: Entertainment Content
B27: 1010121010 | C27: 5 | D27: Film & TV Production & Distr | E27: ⇒ | F27: 3114 | G27: Entertainment Content
B28: 101012101010 | C28: 6 | D28: Film & TV Production | E28: ⇒ | F28: 3114 | G28: Entertainment Content
B29: 10101210101010 | C29: 7 | D29: Film Production | E29: ⇒ | F29: 3114 | G29: Entertainment Content
B30: 10101210101011 | C30: 7 | D30: TV & Video Production | E30: ⇒ | F30: 3114 | G30: Entertainment Content
B31: 101012101011 | C31: 6 | D31: Film & Video Distribution | E31: ⇒ | F31: 3114 | G31: Entertainment Content
B32: 10101210101110 | C32: 7 | D32: Film Distribution | E32: ⇒ | F32: 3114 | G32: Entertainment Content
B33: 10101210101111 | C33: 7 | D33: TV Show Syndication | E33: ⇒ | F33: 3114 | G33: Entertainment Content
B34: 101012101012 | C34: 6 | D34: Teleprod & Postprod Services | E34: ⇒ | F34: 3114 | G34: Entertainment Content
B35: 101012101013 | C35: 6 | D35: Online Film & TV Streaming | E35: ⇒ | F35: 3114 | G35: Entertainment Content
B36: 1010121011 | C36: 5 | D36: TV Media Networks | E36: ⇒ | F36: 3114 | G36: Entertainment Content
B37: 101012101110 | C37: 6 | D37: Cable Networks | E37: ⇒ | F37: 3114 | G37: Entertainment Content
... B50: 1010121211 | C50: 5 | D50: Console & PC Games | E50: ⇒ | F50: 3812 | G50: Software & Services
B51: 101013 | C51: 3 | D51: Publishing & Broadcasting | E51: ⇒
B52: 10101310 | C52: 4 | D52: Publishing | E52: ⇒ | F52: 3115 | G52: Publishing & Broadcasting
...

Sheet Comparison Template
B1: LANGUAGE: | F1: Back to Table of Contents
B2: English | C2: DX616= | D2: =INDEX('How To Download'!$E$70:$E$80,MATCH('Comparison Template'!B2,'How To Download'!$D$70:$D$80,FALSE)) -> 1 | E2: BICS 2024
B3: Enter Identifier | C3: ID_BB_COMPANY | D3: SECURITY_NAME | E3: Level 1 - Sector | G3: Level 2 - Industry Group | I3: Level 3 - Industry | K3: Level 4 - Sub-Industry | M3: Level 5 - Segment | O3: Level 6 - Segment | Q3: Level 7 - Segment
E4: CLASSIFICATION_LEVEL_1_CODE | F4: CLASSIFICATION_LEVEL_1_NAME | G4: CLASSIFICATION_LEVEL_2_CODE | H4: CLASSIFICATION_LEVEL_2_NAME | I4: CLASSIFICATION_LEVEL_3_CODE | J4: CLASSIFICATION_LEVEL_3_NAME | K4: CLASSIFICATION_LEVEL_4_CODE | L4: CLASSIFICATION_LEVEL_4_NAME | M4: CLASSIFICATION_LEVEL_5_CODE | N4: CLASSIFICATION_LEVEL_5_NAME | O4: CLASSIFICATION_LEVEL_6_CODE | P4: CLASSIFICATION_LEVEL_6_NAME | Q4: CLASSIFICATION_LEVEL_7_CODE | R4: CLASSIFICATION_LEVEL_7_NAME
