Workbook

Sheet READ_ME
A1: FIDV · 后三类试拉表 · Communications Equipment L5–L7（带到彭博机刷新，不要在开发机开 BQL）
A3: 试拉范围：Technology / Technology Hardware / Communications Equipment。bicsCode 19101010。
A4: 从 BICS_Technology.xlsx 筛 Level4=Communications Equipment，577 家，一 ticker 一行，A–F 锁值。N 列锁原表 Level4 作核对。
A5: 后三类与前四类一样是证券 BICS 属性：一企一行更深 get()/_xll.BQL。不要用 segments()（那是产品/地区财务段）。
A6: G / I / K 写法与 FOMULAR EXAMPLE 同一外壳，字段名来自 CONFIG!B12–B14（须上机 FLDS 补全；BQLX.pdf 无 L5–L7 字段名）。
A7: G =_xll.BQL("['"&C行&"']", CONFIG!$B$12) → Level5 英文短名
A8: I =_xll.BQL("['"&C行&"']", CONFIG!$B$13) → Level6
A9: K =_xll.BQL("['"&C行&"']", CONFIG!$B$14) → Level7
A10: 2024 库本 L4 下应能见到的短名（抽查，不是公式）：
A11: L5: Broadcasting Equipment · Data Networking Equipment · Mobile Phones · Telecommunications Equipment
A12: L6: Home & Sm Business Netw Equip · Wireless/Wireline Data Network Equip · Wireless/Wireline Telecom Equipment
A13: L7: 仅 Telecommunications Equipment 两条 L6 之下（Mobile Radio、RFID、Satellite、Fiber Optic 等）。Broadcasting / Mobile Phones 为 L5 浅叶，L6/L7 预期 #N/A。
... A24: 禁止：债券 BCLASS；把 segments() 当 BICS；在开发机编造 bics_level_5_* 当真源。

Sheet CONFIG
A1: FIDV · L5–L7 字段名（先填本表，再刷新 CommsEq）
A3: 本 PDF（BQLX）只证实证券上 get() 用 bics_level_1_sector_name 一类「一票一值」分类字段。
A4: L2–L4 的真源是 FOMULAR EXAMPLE 的 _xll.BQL，不是本 PDF 字段表：
A5: bics_level_2_industry_group_name()
A6: bics_level_3_industry_name()
A7: bics_level_4_sub_industry_name()
A8: L5/L6/L7 的 mnemonic 未出现在 BQLX.pdf。不要猜、不要用债券 classification_name(BCLASS)、不要用 segments()。
A9: 上机：FLDS 或 BQL Builder，从已证实的 L1/L4 名往下自动完成，把完整字段名（含括号）粘到 B12–B14。
A10: CommsEq!G/I/K 引用这些单元格。空着刷新会失败，属预期。
A11: 浅叶（如 Mobile Phones 止于 L5）L6/L7 的 #N/A 是分类无该级，保留。Compute Capacity / Timed Out 则减批（M 列）。
A12: Level5 mnemonic | C12: 例：上机确认后再贴，不要把 bics_level_5_* 当已经证实。
A13: Level6 mnemonic
A14: Level7 mnemonic

Sheet TREE
A1: BICS 2024 子树（Communications Equipment 19101010）· 对照用 · 不是彭博返回值
A3: level | B3: bicsCode | C3: name | D3: isLeaf
A4: 4 | B4: 19101010 | C4: Communications Equipment | D4: FALSE
A5: 5 | B5: 1910101010 | C5: Broadcasting Equipment | D5: TRUE
A6: 5 | B6: 1910101011 | C6: Data Networking Equipment | D6: FALSE
A7: 6 | B7: 191010101110 | C7: Home & Sm Business Netw Equip | D7: TRUE
A8: 6 | B8: 191010101111 | C8: Wireless Data Network Equip | D8: TRUE
A9: 6 | B9: 191010101112 | C9: Wireline Data Network Equip | D9: TRUE
A10: 5 | B10: 1910101012 | C10: Mobile Phones | D10: TRUE
A11: 5 | B11: 1910101013 | C11: Telecommunications Equipment | D11: FALSE
A12: 6 | B12: 191010101310 | C12: Wireless Telecom Equipment | D12: FALSE
A13: 7 | B13: 19101010131010 | C13: Mobile Radio Comm Equipment | D13: TRUE
A14: 7 | B14: 19101010131011 | C14: RFID Devices | D14: TRUE
A15: 7 | B15: 19101010131012 | C15: Satellite Communications Equip | D15: TRUE
... A23: 7 | B23: 19101010131114 | C23: Wireline Network Infra Equip | D23: TRUE

Sheet CommsEq
A1: Primary Classification_Technology | B1: Member Companies | C1: Member Ticker | D1: Mkt Cap | E1: Ind Rev | F1: % Tot Rev | G1: Level5 | H1: %Tot Rev l5 | I1: Level6 | J1: %Tot Rev l6 | K1: Level7 | L1: %Tot Rev l7 | M1: BQL batch | N1: Level4_lock
B2: APPLE INC | C2: AAPL US Equity | D2: 4902480000000 | E2: 307003000000 | F2: 73.770248 | G2: {=_xll.BQL("['"&C2&"']", CONFIG!$B$12)} | I2: {=_xll.BQL("['"&C2&"']", CONFIG!$B$13)} | K2: {=_xll.BQL("['"&C2&"']", CONFIG!$B$14)} | M2: BATCH 01 rows 2-501 | N2: Communications Equipment
B3: SAMSUNG ELECTRON | C3: 005930 KS Equity | D3: 1220790000000 | E3: 2.3424028e+11 | F3: 100 | G3: {=_xll.BQL("['"&C3&"']", CONFIG!$B$12)} | I3: {=_xll.BQL("['"&C3&"']", CONFIG!$B$13)} | K3: {=_xll.BQL("['"&C3&"']", CONFIG!$B$14)} | M3: 1 | N3: Communications Equipment
B4: SHENZHEN HUAWEI | C4: KMCACZ CH Equity | E4: 1.2259461e+11 | F4: 100 | G4: {=_xll.BQL("['"&C4&"']", CONFIG!$B$12)} | I4: {=_xll.BQL("['"&C4&"']", CONFIG!$B$13)} | K4: {=_xll.BQL("['"&C4&"']", CONFIG!$B$14)} | M4: 1 | N4: Communications Equipment
B5: CISCO SYSTEMS | C5: CSCO US Equity | D5: 421739000000 | E5: 63325000000 | F5: 100 | G5: {=_xll.BQL("['"&C5&"']", CONFIG!$B$12)} | I5: {=_xll.BQL("['"&C5&"']", CONFIG!$B$13)} | K5: {=_xll.BQL("['"&C5&"']", CONFIG!$B$14)} | M5: 1 | N5: Communications Equipment
B6: XIAOMI CORP-W | C6: 1810 HK Equity | D6: 85073200000 | E6: 3.3526225e+10 | F6: 88.75477 | G6: {=_xll.BQL("['"&C6&"']", CONFIG!$B$12)} | I6: {=_xll.BQL("['"&C6&"']", CONFIG!$B$13)} | K6: {=_xll.BQL("['"&C6&"']", CONFIG!$B$14)} | M6: 1 | N6: Communications Equipment
B7: ERICSSON LM-B | C7: ERICB SS Equity | D7: 32414400000 | E7: 2.411284e+10 | F7: 100 | G7: {=_xll.BQL("['"&C7&"']", CONFIG!$B$12)} | I7: {=_xll.BQL("['"&C7&"']", CONFIG!$B$13)} | K7: {=_xll.BQL("['"&C7&"']", CONFIG!$B$14)} | M7: 1 | N7: Communications Equipment
B8: NOKIA OYJ | C8: NOKIA FH Equity | D8: 61222200000 | E8: 2.2442323e+10 | F8: 100 | G8: {=_xll.BQL("['"&C8&"']", CONFIG!$B$12)} | I8: {=_xll.BQL("['"&C8&"']", CONFIG!$B$13)} | K8: {=_xll.BQL("['"&C8&"']", CONFIG!$B$14)} | M8: 1 | N8: Communications Equipment
B9: ZTE CORP-A | C9: 000063 CH Equity | D9: 21339300000 | E9: 1.8633327e+10 | F9: 100 | G9: {=_xll.BQL("['"&C9&"']", CONFIG!$B$12)} | I9: {=_xll.BQL("['"&C9&"']", CONFIG!$B$13)} | K9: {=_xll.BQL("['"&C9&"']", CONFIG!$B$14)} | M9: 1 | N9: Communications Equipment
B10: MOTOROLA SOLUTIO | C10: MSI US Equity | D10: 75284800000 | E10: 11682000000 | F10: 100 | G10: {=_xll.BQL("['"&C10&"']", CONFIG!$B$12)} | I10: {=_xll.BQL("['"&C10&"']", CONFIG!$B$13)} | K10: {=_xll.BQL("['"&C10&"']", CONFIG!$B$14)} | M10: 1 | N10: Communications Equipment
B11: CORNING INC | C11: GLW US Equity | D11: 132783000000 | E11: 11431000000 | F11: 73.139676 | G11: {=_xll.BQL("['"&C11&"']", CONFIG!$B$12)} | I11: {=_xll.BQL("['"&C11&"']", CONFIG!$B$13)} | K11: {=_xll.BQL("['"&C11&"']", CONFIG!$B$14)} | M11: 1 | N11: Communications Equipment
B12: SHENZHEN TRANS-A | C12: 688036 CH Equity | D12: 9417710000 | E12: 9.1278894e+09 | F12: 100 | G12: {=_xll.BQL("['"&C12&"']", CONFIG!$B$12)} | I12: {=_xll.BQL("['"&C12&"']", CONFIG!$B$13)} | K12: {=_xll.BQL("['"&C12&"']", CONFIG!$B$14)} | M12: 1 | N12: Communications Equipment
B13: ARISTA NETWORKS | C13: ANET US Equity | D13: 259434000000 | E13: 9005700000 | F13: 100 | G13: {=_xll.BQL("['"&C13&"']", CONFIG!$B$12)} | I13: {=_xll.BQL("['"&C13&"']", CONFIG!$B$13)} | K13: {=_xll.BQL("['"&C13&"']", CONFIG!$B$14)} | M13: 1 | N13: Communications Equipment
B14: ACCTON TECH | C14: 2345 TT Equity | D14: 33405200000 | E14: 7.974247e+09 | F14: 100 | G14: {=_xll.BQL("['"&C14&"']", CONFIG!$B$12)} | I14: {=_xll.BQL("['"&C14&"']", CONFIG!$B$13)} | K14: {=_xll.BQL("['"&C14&"']", CONFIG!$B$14)} | M14: 1 | N14: Communications Equipment
B15: SHENZHEN AISI-A | C15: 002416 CH Equity | D15: 1672510000 | E15: 6.6881579e+09 | F15: 87.029852 | G15: {=_xll.BQL("['"&C15&"']", CONFIG!$B$12)} | I15: {=_xll.BQL("['"&C15&"']", CONFIG!$B$13)} | K15: {=_xll.BQL("['"&C15&"']", CONFIG!$B$14)} | M15: 1 | N15: Communications Equipment
B16: FUJIKURA LTD | C16: 5803 JP Equity | D16: 55752800000 | E16: 6.5175222e+09 | F16: 83.076712 | G16: {=_xll.BQL("['"&C16&"']", CONFIG!$B$12)} | I16: {=_xll.BQL("['"&C16&"']", CONFIG!$B$13)} | K16: {=_xll.BQL("['"&C16&"']", CONFIG!$B$14)} | M16: 1 | N16: Communications Equipment
... B19: EOPTOLINK TECH-A | C19: 300502 CH Equity | D19: 90375600000 | E19: 3.4570732e+09 | F19: 100 | G19: {=_xll.BQL("['"&C19&"']", CONFIG!$B$12)} | I19: {=_xll.BQL("['"&C19&"']", CONFIG!$B$13)} | K19: {=_xll.BQL("['"&C19&"']", CONFIG!$B$14)} | M19: 1 | N19: Communications Equipment
B20: SHAANXI ELECTRON | C20: SAXIEZ CH Equity | E20: 3.3334605e+09 | F20: 100 | G20: {=_xll.BQL("['"&C20&"']", CONFIG!$B$12)} | I20: {=_xll.BQL("['"&C20&"']", CONFIG!$B$13)} | K20: {=_xll.BQL("['"&C20&"']", CONFIG!$B$14)} | M20: 1 | N20: Communications Equipment
B21: UBIQUITI INC | C21: UI US Equity | D21: 34084100000 | E21: 3274162000 | F21: 100 | G21: {=_xll.BQL("['"&C21&"']", CONFIG!$B$12)} | I21: {=_xll.BQL("['"&C21&"']", CONFIG!$B$13)} | K21: {=_xll.BQL("['"&C21&"']", CONFIG!$B$14)} | M21: 1 | N21: Communications Equipment
B22: F5 INC | C22: FFIV US Equity | D22: 25286900000 | E22: 3088432000 | F22: 100 | G22: {=_xll.BQL("['"&C22&"']", CONFIG!$B$12)} | I22: {=_xll.BQL("['"&C22&"']", CONFIG!$B$13)} | K22: {=_xll.BQL("['"&C22&"']", CONFIG!$B$14)} | M22: 1 | N22: Communications Equipment
B23: FIBERHOME TELE-A | C23: 600498 CH Equity | D23: 8311000000 | E23: 2.8200676e+09 | F23: 81.322763 | G23: {=_xll.BQL("['"&C23&"']", CONFIG!$B$12)} | I23: {=_xll.BQL("['"&C23&"']", CONFIG!$B$13)} | K23: {=_xll.BQL("['"&C23&"']", CONFIG!$B$14)} | M23: 1 | N23: Communications Equipment
B24: OKI ELECTRIC IND | C24: 6703 JP Equity | D24: 1524540000 | E24: 2.7975727e+09 | F24: 100 | G24: {=_xll.BQL("['"&C24&"']", CONFIG!$B$12)} | I24: {=_xll.BQL("['"&C24&"']", CONFIG!$B$13)} | K24: {=_xll.BQL("['"&C24&"']", CONFIG!$B$14)} | M24: 1 | N24: Communications Equipment
B25: VANTIVA SA | C25: VANTI FP Equity | D25: 43301100 | E25: 1.957881e+09 | F25: 100 | G25: {=_xll.BQL("['"&C25&"']", CONFIG!$B$12)} | I25: {=_xll.BQL("['"&C25&"']", CONFIG!$B$13)} | K25: {=_xll.BQL("['"&C25&"']", CONFIG!$B$14)} | M25: 1 | N25: Communications Equipment
B26: VISTANCE NETWORK | C26: VISN US Equity | D26: 1464480000 | E26: 1931600000 | F26: 100 | G26: {=_xll.BQL("['"&C26&"']", CONFIG!$B$12)} | I26: {=_xll.BQL("['"&C26&"']", CONFIG!$B$13)} | K26: {=_xll.BQL("['"&C26&"']", CONFIG!$B$14)} | M26: 1 | N26: Communications Equipment
B27: ACCELINK TECH-A | C27: 002281 CH Equity | D27: 22442300000 | E27: 1.6600362e+09 | F27: 100 | G27: {=_xll.BQL("['"&C27&"']", CONFIG!$B$12)} | I27: {=_xll.BQL("['"&C27&"']", CONFIG!$B$13)} | K27: {=_xll.BQL("['"&C27&"']", CONFIG!$B$14)} | M27: 1 | N27: Communications Equipment
B28: YOFC-H | C28: 6869 HK Equity | D28: 36536700000 | E28: 1.5990156e+09 | F28: 100 | G28: {=_xll.BQL("['"&C28&"']", CONFIG!$B$12)} | I28: {=_xll.BQL("['"&C28&"']", CONFIG!$B$13)} | K28: {=_xll.BQL("['"&C28&"']", CONFIG!$B$14)} | M28: 1 | N28: Communications Equipment
B29: VIAVI SOLUTIONS | C29: VIAV US Equity | D29: 9186500000 | E29: 1518300000 | F29: 100 | G29: {=_xll.BQL("['"&C29&"']", CONFIG!$B$12)} | I29: {=_xll.BQL("['"&C29&"']", CONFIG!$B$13)} | K29: {=_xll.BQL("['"&C29&"']", CONFIG!$B$14)} | M29: 1 | N29: Communications Equipment
B30: MERRY ELEC | C30: 2439 TT Equity | D30: 610845000 | E30: 1.4929584e+09 | F30: 100 | G30: {=_xll.BQL("['"&C30&"']", CONFIG!$B$12)} | I30: {=_xll.BQL("['"&C30&"']", CONFIG!$B$13)} | K30: {=_xll.BQL("['"&C30&"']", CONFIG!$B$14)} | M30: 1 | N30: Communications Equipment
B31: GN STORE NORD | C31: GN DC Equity | D31: 2321010000 | E31: 1.4458528e+09 | F31: 57.013467 | G31: {=_xll.BQL("['"&C31&"']", CONFIG!$B$12)} | I31: {=_xll.BQL("['"&C31&"']", CONFIG!$B$13)} | K31: {=_xll.BQL("['"&C31&"']", CONFIG!$B$14)} | M31: 1 | N31: Communications Equipment
B32: EXTREME NETWORKS | C32: EXTR US Equity | D32: 2860170000 | E32: 1283593000 | F32: 100 | G32: {=_xll.BQL("['"&C32&"']", CONFIG!$B$12)} | I32: {=_xll.BQL("['"&C32&"']", CONFIG!$B$13)} | K32: {=_xll.BQL("['"&C32&"']", CONFIG!$B$14)} | M32: 1 | N32: Communications Equipment
... B69: KAON GROUP CO LT | C69: 078890 KS Equity | D69: 59833500 | E69: 3.6394794e+08 | F69: 100 | G69: {=_xll.BQL("['"&C69&"']", CONFIG!$B$12)} | I69: {=_xll.BQL("['"&C69&"']", CONFIG!$B$13)} | K69: {=_xll.BQL("['"&C69&"']", CONFIG!$B$14)} | M69: 1 | N69: Communications Equipment
B70: FS COM LTD/CHI-A | C70: 2099320D CH Equity | E70: 3.6273777e+08 | F70: 100 | G70: {=_xll.BQL("['"&C70&"']", CONFIG!$B$12)} | I70: {=_xll.BQL("['"&C70&"']", CONFIG!$B$13)} | K70: {=_xll.BQL("['"&C70&"']", CONFIG!$B$14)} | M70: 1 | N70: Communications Equipment
B71: HARMONIC INC | C71: HLIT US Equity | D71: 1193730000 | E71: 360523000 | F71: 100 | G71: {=_xll.BQL("['"&C71&"']", CONFIG!$B$12)} | I71: {=_xll.BQL("['"&C71&"']", CONFIG!$B$13)} | K71: {=_xll.BQL("['"&C71&"']", CONFIG!$B$14)} | M71: 1 | N71: Communications Equipment
B72: ASCOM HOLDIN-REG | C72: ASCN SW Equity | D72: 257619000 | E72: 3.5157623e+08 | F72: 100 | G72: {=_xll.BQL("['"&C72&"']", CONFIG!$B$12)} | I72: {=_xll.BQL("['"&C72&"']", CONFIG!$B$13)} | K72: {=_xll.BQL("['"&C72&"']", CONFIG!$B$14)} | M72: 1 | N72: Communications Equipment
B73: SHENZHEN NEOWA-A | C73: 688159 CH Equity | D73: 506275000 | E73: 3.3285595e+08 | F73: 99.470723 | G73: {=_xll.BQL("['"&C73&"']", CONFIG!$B$12)} | I73: {=_xll.BQL("['"&C73&"']", CONFIG!$B$13)} | K73: {=_xll.BQL("['"&C73&"']", CONFIG!$B$14)} | M73: 1 | N73: Communications Equipment
B74: HFCL LTD | C74: HMFC IN Equity | D74: 3370490000 | E74: 3.3172088e+08 | F74: 60.028222 | G74: {=_xll.BQL("['"&C74&"']", CONFIG!$B$12)} | I74: {=_xll.BQL("['"&C74&"']", CONFIG!$B$13)} | K74: {=_xll.BQL("['"&C74&"']", CONFIG!$B$14)} | M74: 1 | N74: Communications Equipment
B75: SPIGEN KOREA CO | C75: 192440 KS Equity | D75: 136172000 | E75: 3.260787e+08 | F75: 100 | G75: {=_xll.BQL("['"&C75&"']", CONFIG!$B$12)} | I75: {=_xll.BQL("['"&C75&"']", CONFIG!$B$13)} | K75: {=_xll.BQL("['"&C75&"']", CONFIG!$B$14)} | M75: 1 | N75: Communications Equipment
B76: VANCHIP TIANJ-A | C76: 688153 CH Equity | D76: 1698630000 | E76: 3.2299264e+08 | F76: 100 | G76: {=_xll.BQL("['"&C76&"']", CONFIG!$B$12)} | I76: {=_xll.BQL("['"&C76&"']", CONFIG!$B$13)} | K76: {=_xll.BQL("['"&C76&"']", CONFIG!$B$14)} | M76: 1 | N76: Communications Equipment
B77: ALLIED TELESIS | C77: 6835 JP Equity | D77: 176897000 | E77: 3.1981735e+08 | F77: 100 | G77: {=_xll.BQL("['"&C77&"']", CONFIG!$B$12)} | I77: {=_xll.BQL("['"&C77&"']", CONFIG!$B$13)} | K77: {=_xll.BQL("['"&C77&"']", CONFIG!$B$14)} | M77: 1 | N77: Communications Equipment
B78: NEDAP N.V. | C78: NEDAP NA Equity | D78: 706116000 | E78: 3.1557635e+08 | F78: 100 | G78: {=_xll.BQL("['"&C78&"']", CONFIG!$B$12)} | I78: {=_xll.BQL("['"&C78&"']", CONFIG!$B$13)} | K78: {=_xll.BQL("['"&C78&"']", CONFIG!$B$14)} | M78: 1 | N78: Communications Equipment
...
